Workbook
Name C_L1: HELP!$B$4
Name C_L2: HELP!$B$5
Name C_L3: HELP!$B$6
Name C_L4: HELP!$B$7
Name C_L5: HELP!$B$8
Name C_L6: HELP!$B$9
Name I_S: Combinations!$P$4
Name LIST: OFFSET(Combinations!$P$7,0,0,_xleta.N)
Name N: HELP!$C$4
Name N_1: HELP!$C$5
Name N_2: HELP!$C$6
Name N_3: HELP!$C$7
Name N_4: HELP!$C$8
Name N_5: HELP!$C$9
Name N_LISTS: HELP!$B$11

Sheet Combinations
A1: COMBINATIONS GENERATOR | L1: =N_LISTS -> 2 | P1: =N -> 210 | R1: indzara.com
B2: ENTER VALUES IN LISTS BELOW | L2: LISTS | P2: COMBINATIONS | R2: Maximum combinations: 500
B3: No Blanks in the middle of any lists | R3: Max Lists: 6
B4: Enter lists sequentially (Eg. do not enter list 5 without list 4) | O4: SEPARATOR
P5: VIEW LIST OF COMBINATIONS BELOW
B6: LIST 1 | D6: LIST 2 | F6: LIST 3 | H6: LIST 4 | J6: LIST 5 | L6: LIST 6 | P6: LIST | R6: DROP DOWN | Z6: LOCATION | AA6: DEPARTMENT | AB6: LOCATION - DEPARTMENT
B7: Peanut Butter, | D7: Peanut Butter | P7: =IFERROR(IF(HELP!$F3>N,"",INDEX(T_L1[],HELP!G3,1) &IF(N_LISTS=1,"",I_S&INDEX(T_L2[],HELP!H3,1) &IF(N_LISTS=2,"",I_S&INDEX(T_L3[],HELP!I3,1) &IF(N_LISTS=3,"",I_S&INDEX(T_L4[],HELP!J3,1) &IF(N_LISTS=4,"",I_S&INDEX(T_L5[],HELP!K3,1) &IF(N_LISTS=5,"",I_S&INDEX(T_L6[],HELP!L3,1))))))),"") -> Peanut Butter, Peanut Butter | R7: Protein Carbs Fats Vegetables | Z7: =IFERROR(INDEX(T_L1[LIST 1],HELP!G3),"") -> Peanut Butter, | AA7: =IF(Z7="","",INDEX(T_L2[LIST 2],HELP!H3)) -> Peanut Butter | AB7: =Z7&" - "&AA7 -> Peanut Butter, - Peanut Butter | AC7: =AA7&" - "&AB7 -> Peanut Butter - Peanut Butter, - Peanut Butter
B8: Almond Butter, | D8: Almond Butter | P8: =IFERROR(IF(HELP!$F4>N,"",INDEX(T_L1[],HELP!G4,1) &IF(N_LISTS=1,"",I_S&INDEX(T_L2[],HELP!H4,1) &IF(N_LISTS=2,"",I_S&INDEX(T_L3[],HELP!I4,1) &IF(N_LISTS=3,"",I_S&INDEX(T_L4[],HELP!J4,1) &IF(N_LISTS=4,"",I_S&INDEX(T_L5[],HELP!K4,1) &IF(N_LISTS=5,"",I_S&INDEX(T_L6[],HELP!L4,1))))))),"") -> Peanut Butter, Almond Butter | Z8: =IFERROR(INDEX(T_L1[LIST 1],HELP!G4),"") -> Peanut Butter, | AA8: =IF(Z8="","",INDEX(T_L2[LIST 2],HELP!H4)) -> Almond Butter | AB8: =Z8&" - "&AA8 -> Peanut Butter, - Almond Butter
B9: Cashew Butter, | D9: Cashew Butter | P9: =IFERROR(IF(HELP!$F5>N,"",INDEX(T_L1[],HELP!G5,1) &IF(N_LISTS=1,"",I_S&INDEX(T_L2[],HELP!H5,1) &IF(N_LISTS=2,"",I_S&INDEX(T_L3[],HELP!I5,1) &IF(N_LISTS=3,"",I_S&INDEX(T_L4[],HELP!J5,1) &IF(N_LISTS=4,"",I_S&INDEX(T_L5[],HELP!K5,1) &IF(N_LISTS=5,"",I_S&INDEX(T_L6[],HELP!L5,1))))))),"") -> Peanut Butter, Cashew Butter | Z9: =IFERROR(INDEX(T_L1[LIST 1],HELP!G5),"") -> Peanut Butter, | AA9: =IF(Z9="","",INDEX(T_L2[LIST 2],HELP!H5)) -> Cashew Butter | AB9: =Z9&" - "&AA9 -> Peanut Butter, - Cashew Butter
B10: Chia Seeds, | D10: Chia Seeds | P10: =IFERROR(IF(HELP!$F6>N,"",INDEX(T_L1[],HELP!G6,1) &IF(N_LISTS=1,"",I_S&INDEX(T_L2[],HELP!H6,1) &IF(N_LISTS=2,"",I_S&INDEX(T_L3[],HELP!I6,1) &IF(N_LISTS=3,"",I_S&INDEX(T_L4[],HELP!J6,1) &IF(N_LISTS=4,"",I_S&INDEX(T_L5[],HELP!K6,1) &IF(N_LISTS=5,"",I_S&INDEX(T_L6[],HELP!L6,1))))))),"") -> Peanut Butter, Chia Seeds | Z10: =IFERROR(INDEX(T_L1[LIST 1],HELP!G6),"") -> Peanut Butter, | AA10: =IF(Z10="","",INDEX(T_L2[LIST 2],HELP!H6)) -> Chia Seeds | AB10: =Z10&" - "&AA10 -> Peanut Butter, - Chia Seeds
B11: Flax Seeds, | D11: Flax Seeds | P11: =IFERROR(IF(HELP!$F7>N,"",INDEX(T_L1[],HELP!G7,1) &IF(N_LISTS=1,"",I_S&INDEX(T_L2[],HELP!H7,1) &IF(N_LISTS=2,"",I_S&INDEX(T_L3[],HELP!I7,1) &IF(N_LISTS=3,"",I_S&INDEX(T_L4[],HELP!J7,1) &IF(N_LISTS=4,"",I_S&INDEX(T_L5[],HELP!K7,1) &IF(N_LISTS=5,"",I_S&INDEX(T_L6[],HELP!L7,1))))))),"") -> Peanut Butter, Flax Seeds | Z11: =IFERROR(INDEX(T_L1[LIST 1],HELP!G7),"") -> Peanut Butter, | AA11: =IF(Z11="","",INDEX(T_L2[LIST 2],HELP!H7)) -> Flax Seeds | AB11: =Z11&" - "&AA11 -> Peanut Butter, - Flax Seeds
B12: Hemp Seeds, | D12: Hemp Seeds | P12: =IFERROR(IF(HELP!$F8>N,"",INDEX(T_L1[],HELP!G8,1) &IF(N_LISTS=1,"",I_S&INDEX(T_L2[],HELP!H8,1) &IF(N_LISTS=2,"",I_S&INDEX(T_L3[],HELP!I8,1) &IF(N_LISTS=3,"",I_S&INDEX(T_L4[],HELP!J8,1) &IF(N_LISTS=4,"",I_S&INDEX(T_L5[],HELP!K8,1) &IF(N_LISTS=5,"",I_S&INDEX(T_L6[],HELP!L8,1))))))),"") -> Peanut Butter, Hemp Seeds | Z12: =IFERROR(INDEX(T_L1[LIST 1],HELP!G8),"") -> Peanut Butter, | AA12: =IF(Z12="","",INDEX(T_L2[LIST 2],HELP!H8)) -> Hemp Seeds | AB12: =Z12&" - "&AA12 -> Peanut Butter, - Hemp Seeds
B13: Avocado, | D13: Avocado | P13: =IFERROR(IF(HELP!$F9>N,"",INDEX(T_L1[],HELP!G9,1) &IF(N_LISTS=1,"",I_S&INDEX(T_L2[],HELP!H9,1) &IF(N_LISTS=2,"",I_S&INDEX(T_L3[],HELP!I9,1) &IF(N_LISTS=3,"",I_S&INDEX(T_L4[],HELP!J9,1) &IF(N_LISTS=4,"",I_S&INDEX(T_L5[],HELP!K9,1) &IF(N_LISTS=5,"",I_S&INDEX(T_L6[],HELP!L9,1))))))),"") -> Peanut Butter, Avocado | Z13: =IFERROR(INDEX(T_L1[LIST 1],HELP!G9),"") -> Peanut Butter, | AA13: =IF(Z13="","",INDEX(T_L2[LIST 2],HELP!H9)) -> Avocado | AB13: =Z13&" - "&AA13 -> Peanut Butter, - Avocado
B14: Coconut Oil, | D14: Coconut Oil | P14: =IFERROR(IF(HELP!$F10>N,"",INDEX(T_L1[],HELP!G10,1) &IF(N_LISTS=1,"",I_S&INDEX(T_L2[],HELP!H10,1) &IF(N_LISTS=2,"",I_S&INDEX(T_L3[],HELP!I10,1) &IF(N_LISTS=3,"",I_S&INDEX(T_L4[],HELP!J10,1) &IF(N_LISTS=4,"",I_S&INDEX(T_L5[],HELP!K10,1) &IF(N_LISTS=5,"",I_S&INDEX(T_L6[],HELP!L10,1))))))),"") -> Peanut Butter, Coconut Oil | Z14: =IFERROR(INDEX(T_L1[LIST 1],HELP!G10),"") -> Peanut Butter, | AA14: =IF(Z14="","",INDEX(T_L2[LIST 2],HELP!H10)) -> Coconut Oil | AB14: =Z14&" - "&AA14 -> Peanut Butter, - Coconut Oil
B15: MCT Oil, | D15: MCT Oil | P15: =IFERROR(IF(HELP!$F11>N,"",INDEX(T_L1[],HELP!G11,1) &IF(N_LISTS=1,"",I_S&INDEX(T_L2[],HELP!H11,1) &IF(N_LISTS=2,"",I_S&INDEX(T_L3[],HELP!I11,1) &IF(N_LISTS=3,"",I_S&INDEX(T_L4[],HELP!J11,1) &IF(N_LISTS=4,"",I_S&INDEX(T_L5[],HELP!K11,1) &IF(N_LISTS=5,"",I_S&INDEX(T_L6[],HELP!L11,1))))))),"") -> Peanut Butter, MCT Oil | Z15: =IFERROR(INDEX(T_L1[LIST 1],HELP!G11),"") -> Peanut Butter, | AA15: =IF(Z15="","",INDEX(T_L2[LIST 2],HELP!H11)) -> MCT Oil | AB15: =Z15&" - "&AA15 -> Peanut Butter, - MCT Oil
B16: Walnuts, | D16: Walnuts | P16: =IFERROR(IF(HELP!$F12>N,"",INDEX(T_L1[],HELP!G12,1) &IF(N_LISTS=1,"",I_S&INDEX(T_L2[],HELP!H12,1) &IF(N_LISTS=2,"",I_S&INDEX(T_L3[],HELP!I12,1) &IF(N_LISTS=3,"",I_S&INDEX(T_L4[],HELP!J12,1) &IF(N_LISTS=4,"",I_S&INDEX(T_L5[],HELP!K12,1) &IF(N_LISTS=5,"",I_S&INDEX(T_L6[],HELP!L12,1))))))),"") -> Peanut Butter, Walnuts | Z16: =IFERROR(INDEX(T_L1[LIST 1],HELP!G12),"") -> Peanut Butter, | AA16: =IF(Z16="","",INDEX(T_L2[LIST 2],HELP!H12)) -> Walnuts | AB16: =Z16&" - "&AA16 -> Peanut Butter, - Walnuts
B17: Pecans, | D17: Pecans | P17: =IFERROR(IF(HELP!$F13>N,"",INDEX(T_L1[],HELP!G13,1) &IF(N_LISTS=1,"",I_S&INDEX(T_L2[],HELP!H13,1) &IF(N_LISTS=2,"",I_S&INDEX(T_L3[],HELP!I13,1) &IF(N_LISTS=3,"",I_S&INDEX(T_L4[],HELP!J13,1) &IF(N_LISTS=4,"",I_S&INDEX(T_L5[],HELP!K13,1) &IF(N_LISTS=5,"",I_S&INDEX(T_L6[],HELP!L13,1))))))),"") -> Peanut Butter, Pecans | Z17: =IFERROR(INDEX(T_L1[LIST 1],HELP!G13),"") -> Peanut Butter, | AA17: =IF(Z17="","",INDEX(T_L2[LIST 2],HELP!H13)) -> Pecans | AB17: =Z17&" - "&AA17 -> Peanut Butter, - Pecans
B18: Macadamia Nuts, | D18: Macadamia Nuts | P18: =IFERROR(IF(HELP!$F14>N,"",INDEX(T_L1[],HELP!G14,1) &IF(N_LISTS=1,"",I_S&INDEX(T_L2[],HELP!H14,1) &IF(N_LISTS=2,"",I_S&INDEX(T_L3[],HELP!I14,1) &IF(N_LISTS=3,"",I_S&INDEX(T_L4[],HELP!J14,1) &IF(N_LISTS=4,"",I_S&INDEX(T_L5[],HELP!K14,1) &IF(N_LISTS=5,"",I_S&INDEX(T_L6[],HELP!L14,1))))))),"") -> Peanut Butter, Macadamia Nuts | Z18: =IFERROR(INDEX(T_L1[LIST 1],HELP!G14),"") -> Peanut Butter, | AA18: =IF(Z18="","",INDEX(T_L2[LIST 2],HELP!H14)) -> Macadamia Nuts | AB18: =Z18&" - "&AA18 -> Peanut Butter, - Macadamia Nuts
B19: Tahini, | D19: Tahini | P19: =IFERROR(IF(HELP!$F15>N,"",INDEX(T_L1[],HELP!G15,1) &IF(N_LISTS=1,"",I_S&INDEX(T_L2[],HELP!H15,1) &IF(N_LISTS=2,"",I_S&INDEX(T_L3[],HELP!I15,1) &IF(N_LISTS=3,"",I_S&INDEX(T_L4[],HELP!J15,1) &IF(N_LISTS=4,"",I_S&INDEX(T_L5[],HELP!K15,1) &IF(N_LISTS=5,"",I_S&INDEX(T_L6[],HELP!L15,1))))))),"") -> Peanut Butter, Tahini | Z19: =IFERROR(INDEX(T_L1[LIST 1],HELP!G15),"") -> Peanut Butter, | AA19: =IF(Z19="","",INDEX(T_L2[LIST 2],HELP!H15)) -> Tahini | AB19: =Z19&" - "&AA19 -> Peanut Butter, - Tahini
B20: Dark Chocolate, | D20: Dark Chocolate | P20: =IFERROR(IF(HELP!$F16>N,"",INDEX(T_L1[],HELP!G16,1) &IF(N_LISTS=1,"",I_S&INDEX(T_L2[],HELP!H16,1) &IF(N_LISTS=2,"",I_S&INDEX(T_L3[],HELP!I16,1) &IF(N_LISTS=3,"",I_S&INDEX(T_L4[],HELP!J16,1) &IF(N_LISTS=4,"",I_S&INDEX(T_L5[],HELP!K16,1) &IF(N_LISTS=5,"",I_S&INDEX(T_L6[],HELP!L16,1))))))),"") -> Peanut Butter, Dark Chocolate | Z20: =IFERROR(INDEX(T_L1[LIST 1],HELP!G16),"") -> Peanut Butter, | AA20: =IF(Z20="","",INDEX(T_L2[LIST 2],HELP!H16)) -> Dark Chocolate | AB20: =Z20&" - "&AA20 -> Peanut Butter, - Dark Chocolate
D21: - | P21: =IFERROR(IF(HELP!$F17>N,"",INDEX(T_L1[],HELP!G17,1) &IF(N_LISTS=1,"",I_S&INDEX(T_L2[],HELP!H17,1) &IF(N_LISTS=2,"",I_S&INDEX(T_L3[],HELP!I17,1) &IF(N_LISTS=3,"",I_S&INDEX(T_L4[],HELP!J17,1) &IF(N_LISTS=4,"",I_S&INDEX(T_L5[],HELP!K17,1) &IF(N_LISTS=5,"",I_S&INDEX(T_L6[],HELP!L17,1))))))),"") -> Peanut Butter, - | Z21: =IFERROR(INDEX(T_L1[LIST 1],HELP!G17),"") -> Peanut Butter, | AA21: =IF(Z21="","",INDEX(T_L2[LIST 2],HELP!H17)) -> - | AB21: =Z21&" - "&AA21 -> Peanut Butter, - -
P22: =IFERROR(IF(HELP!$F18>N,"",INDEX(T_L1[],HELP!G18,1) &IF(N_LISTS=1,"",I_S&INDEX(T_L2[],HELP!H18,1) &IF(N_LISTS=2,"",I_S&INDEX(T_L3[],HELP!I18,1) &IF(N_LISTS=3,"",I_S&INDEX(T_L4[],HELP!J18,1) &IF(N_LISTS=4,"",I_S&INDEX(T_L5[],HELP!K18,1) &IF(N_LISTS=5,"",I_S&INDEX(T_L6[],HELP!L18,1))))))),"") -> Almond Butter, Peanut Butter | Z22: =IFERROR(INDEX(T_L1[LIST 1],HELP!G18),"") -> Almond Butter, | AA22: =IF(Z22="","",INDEX(T_L2[LIST 2],HELP!H18)) -> Peanut Butter | AB22: =Z22&" - "&AA22 -> Almond Butter, - Peanut Butter
P23: =IFERROR(IF(HELP!$F19>N,"",INDEX(T_L1[],HELP!G19,1) &IF(N_LISTS=1,"",I_S&INDEX(T_L2[],HELP!H19,1) &IF(N_LISTS=2,"",I_S&INDEX(T_L3[],HELP!I19,1) &IF(N_LISTS=3,"",I_S&INDEX(T_L4[],HELP!J19,1) &IF(N_LISTS=4,"",I_S&INDEX(T_L5[],HELP!K19,1) &IF(N_LISTS=5,"",I_S&INDEX(T_L6[],HELP!L19,1))))))),"") -> Almond Butter, Almond Butter | Z23: =IFERROR(INDEX(T_L1[LIST 1],HELP!G19),"") -> Almond Butter, | AA23: =IF(Z23="","",INDEX(T_L2[LIST 2],HELP!H19)) -> Almond Butter | AB23: =Z23&" - "&AA23 -> Almond Butter, - Almond Butter
P24: =IFERROR(IF(HELP!$F20>N,"",INDEX(T_L1[],HELP!G20,1) &IF(N_LISTS=1,"",I_S&INDEX(T_L2[],HELP!H20,1) &IF(N_LISTS=2,"",I_S&INDEX(T_L3[],HELP!I20,1) &IF(N_LISTS=3,"",I_S&INDEX(T_L4[],HELP!J20,1) &IF(N_LISTS=4,"",I_S&INDEX(T_L5[],HELP!K20,1) &IF(N_LISTS=5,"",I_S&INDEX(T_L6[],HELP!L20,1))))))),"") -> Almond Butter, Cashew Butter | Z24: =IFERROR(INDEX(T_L1[LIST 1],HELP!G20),"") -> Almond Butter, | AA24: =IF(Z24="","",INDEX(T_L2[LIST 2],HELP!H20)) -> Cashew Butter | AB24: =Z24&" - "&AA24 -> Almond Butter, - Cashew Butter
P25: =IFERROR(IF(HELP!$F21>N,"",INDEX(T_L1[],HELP!G21,1) &IF(N_LISTS=1,"",I_S&INDEX(T_L2[],HELP!H21,1) &IF(N_LISTS=2,"",I_S&INDEX(T_L3[],HELP!I21,1) &IF(N_LISTS=3,"",I_S&INDEX(T_L4[],HELP!J21,1) &IF(N_LISTS=4,"",I_S&INDEX(T_L5[],HELP!K21,1) &IF(N_LISTS=5,"",I_S&INDEX(T_L6[],HELP!L21,1))))))),"") -> Almond Butter, Chia Seeds | Z25: =IFERROR(INDEX(T_L1[LIST 1],HELP!G21),"") -> Almond Butter, | AA25: =IF(Z25="","",INDEX(T_L2[LIST 2],HELP!H21)) -> Chia Seeds | AB25: =Z25&" - "&AA25 -> Almond Butter, - Chia Seeds
P26: =IFERROR(IF(HELP!$F22>N,"",INDEX(T_L1[],HELP!G22,1) &IF(N_LISTS=1,"",I_S&INDEX(T_L2[],HELP!H22,1) &IF(N_LISTS=2,"",I_S&INDEX(T_L3[],HELP!I22,1) &IF(N_LISTS=3,"",I_S&INDEX(T_L4[],HELP!J22,1) &IF(N_LISTS=4,"",I_S&INDEX(T_L5[],HELP!K22,1) &IF(N_LISTS=5,"",I_S&INDEX(T_L6[],HELP!L22,1))))))),"") -> Almond Butter, Flax Seeds | Z26: =IFERROR(INDEX(T_L1[LIST 1],HELP!G22),"") -> Almond Butter, | AA26: =IF(Z26="","",INDEX(T_L2[LIST 2],HELP!H22)) -> Flax Seeds | AB26: =Z26&" - "&AA26 -> Almond Butter, - Flax Seeds
P27: =IFERROR(IF(HELP!$F23>N,"",INDEX(T_L1[],HELP!G23,1) &IF(N_LISTS=1,"",I_S&INDEX(T_L2[],HELP!H23,1) &IF(N_LISTS=2,"",I_S&INDEX(T_L3[],HELP!I23,1) &IF(N_LISTS=3,"",I_S&INDEX(T_L4[],HELP!J23,1) &IF(N_LISTS=4,"",I_S&INDEX(T_L5[],HELP!K23,1) &IF(N_LISTS=5,"",I_S&INDEX(T_L6[],HELP!L23,1))))))),"") -> Almond Butter, Hemp Seeds | Z27: =IFERROR(INDEX(T_L1[LIST 1],HELP!G23),"") -> Almond Butter, | AA27: =IF(Z27="","",INDEX(T_L2[LIST 2],HELP!H23)) -> Hemp Seeds | AB27: =Z27&" - "&AA27 -> Almond Butter, - Hemp Seeds
P28: =IFERROR(IF(HELP!$F24>N,"",INDEX(T_L1[],HELP!G24,1) &IF(N_LISTS=1,"",I_S&INDEX(T_L2[],HELP!H24,1) &IF(N_LISTS=2,"",I_S&INDEX(T_L3[],HELP!I24,1) &IF(N_LISTS=3,"",I_S&INDEX(T_L4[],HELP!J24,1) &IF(N_LISTS=4,"",I_S&INDEX(T_L5[],HELP!K24,1) &IF(N_LISTS=5,"",I_S&INDEX(T_L6[],HELP!L24,1))))))),"") -> Almond Butter, Avocado | Z28: =IFERROR(INDEX(T_L1[LIST 1],HELP!G24),"") -> Almond Butter, | AA28: =IF(Z28="","",INDEX(T_L2[LIST 2],HELP!H24)) -> Avocado | AB28: =Z28&" - "&AA28 -> Almond Butter, - Avocado
P29: =IFERROR(IF(HELP!$F25>N,"",INDEX(T_L1[],HELP!G25,1) &IF(N_LISTS=1,"",I_S&INDEX(T_L2[],HELP!H25,1) &IF(N_LISTS=2,"",I_S&INDEX(T_L3[],HELP!I25,1) &IF(N_LISTS=3,"",I_S&INDEX(T_L4[],HELP!J25,1) &IF(N_LISTS=4,"",I_S&INDEX(T_L5[],HELP!K25,1) &IF(N_LISTS=5,"",I_S&INDEX(T_L6[],HELP!L25,1))))))),"") -> Almond Butter, Coconut Oil | Z29: =IFERROR(INDEX(T_L1[LIST 1],HELP!G25),"") -> Almond Butter, | AA29: =IF(Z29="","",INDEX(T_L2[LIST 2],HELP!H25)) -> Coconut Oil | AB29: =Z29&" - "&AA29 -> Almond Butter, - Coconut Oil
P30: =IFERROR(IF(HELP!$F26>N,"",INDEX(T_L1[],HELP!G26,1) &IF(N_LISTS=1,"",I_S&INDEX(T_L2[],HELP!H26,1) &IF(N_LISTS=2,"",I_S&INDEX(T_L3[],HELP!I26,1) &IF(N_LISTS=3,"",I_S&INDEX(T_L4[],HELP!J26,1) &IF(N_LISTS=4,"",I_S&INDEX(T_L5[],HELP!K26,1) &IF(N_LISTS=5,"",I_S&INDEX(T_L6[],HELP!L26,1))))))),"") -> Almond Butter, MCT Oil | Z30: =IFERROR(INDEX(T_L1[LIST 1],HELP!G26),"") -> Almond Butter, | AA30: =IF(Z30="","",INDEX(T_L2[LIST 2],HELP!H26)) -> MCT Oil | AB30: =Z30&" - "&AA30 -> Almond Butter, - MCT Oil
P31: =IFERROR(IF(HELP!$F27>N,"",INDEX(T_L1[],HELP!G27,1) &IF(N_LISTS=1,"",I_S&INDEX(T_L2[],HELP!H27,1) &IF(N_LISTS=2,"",I_S&INDEX(T_L3[],HELP!I27,1) &IF(N_LISTS=3,"",I_S&INDEX(T_L4[],HELP!J27,1) &IF(N_LISTS=4,"",I_S&INDEX(T_L5[],HELP!K27,1) &IF(N_LISTS=5,"",I_S&INDEX(T_L6[],HELP!L27,1))))))),"") -> Almond Butter, Walnuts | Z31: =IFERROR(INDEX(T_L1[LIST 1],HELP!G27),"") -> Almond Butter, | AA31: =IF(Z31="","",INDEX(T_L2[LIST 2],HELP!H27)) -> Walnuts | AB31: =Z31&" - "&AA31 -> Almond Butter, - Walnuts
P32: =IFERROR(IF(HELP!$F28>N,"",INDEX(T_L1[],HELP!G28,1) &IF(N_LISTS=1,"",I_S&INDEX(T_L2[],HELP!H28,1) &IF(N_LISTS=2,"",I_S&INDEX(T_L3[],HELP!I28,1) &IF(N_LISTS=3,"",I_S&INDEX(T_L4[],HELP!J28,1) &IF(N_LISTS=4,"",I_S&INDEX(T_L5[],HELP!K28,1) &IF(N_LISTS=5,"",I_S&INDEX(T_L6[],HELP!L28,1))))))),"") -> Almond Butter, Pecans | Z32: =IFERROR(INDEX(T_L1[LIST 1],HELP!G28),"") -> Almond Butter, | AA32: =IF(Z32="","",INDEX(T_L2[LIST 2],HELP!H28)) -> Pecans | AB32: =Z32&" - "&AA32 -> Almond Butter, - Pecans
P33: =IFERROR(IF(HELP!$F29>N,"",INDEX(T_L1[],HELP!G29,1) &IF(N_LISTS=1,"",I_S&INDEX(T_L2[],HELP!H29,1) &IF(N_LISTS=2,"",I_S&INDEX(T_L3[],HELP!I29,1) &IF(N_LISTS=3,"",I_S&INDEX(T_L4[],HELP!J29,1) &IF(N_LISTS=4,"",I_S&INDEX(T_L5[],HELP!K29,1) &IF(N_LISTS=5,"",I_S&INDEX(T_L6[],HELP!L29,1))))))),"") -> Almond Butter, Macadamia Nuts | Z33: =IFERROR(INDEX(T_L1[LIST 1],HELP!G29),"") -> Almond Butter, | AA33: =IF(Z33="","",INDEX(T_L2[LIST 2],HELP!H29)) -> Macadamia Nuts | AB33: =Z33&" - "&AA33 -> Almond Butter, - Macadamia Nuts
... P286: =IFERROR(IF(HELP!$F282>N,"",INDEX(T_L1[],HELP!G282,1) &IF(N_LISTS=1,"",I_S&INDEX(T_L2[],HELP!H282,1) &IF(N_LISTS=2,"",I_S&INDEX(T_L3[],HELP!I282,1) &IF(N_LISTS=3,"",I_S&INDEX(T_L4[],HELP!J282,1) &IF(N_LISTS=4,"",I_S&INDEX(T_L5[],HELP!K282,1) &IF(N_LISTS=5,"",I_S&INDEX(T_L6[],HELP!L282,1))))))),"") | Z286: =IFERROR(INDEX(T_L1[LIST 1],HELP!G282),"") | AA286: =IF(Z286="","",INDEX(T_L2[LIST 2],HELP!H282)) | AB286: =Z286&" - "&AA286 -> -
P287: =IFERROR(IF(HELP!$F283>N,"",INDEX(T_L1[],HELP!G283,1) &IF(N_LISTS=1,"",I_S&INDEX(T_L2[],HELP!H283,1) &IF(N_LISTS=2,"",I_S&INDEX(T_L3[],HELP!I283,1) &IF(N_LISTS=3,"",I_S&INDEX(T_L4[],HELP!J283,1) &IF(N_LISTS=4,"",I_S&INDEX(T_L5[],HELP!K283,1) &IF(N_LISTS=5,"",I_S&INDEX(T_L6[],HELP!L283,1))))))),"")
P288: =IFERROR(IF(HELP!$F284>N,"",INDEX(T_L1[],HELP!G284,1) &IF(N_LISTS=1,"",I_S&INDEX(T_L2[],HELP!H284,1) &IF(N_LISTS=2,"",I_S&INDEX(T_L3[],HELP!I284,1) &IF(N_LISTS=3,"",I_S&INDEX(T_L4[],HELP!J284,1) &IF(N_LISTS=4,"",I_S&INDEX(T_L5[],HELP!K284,1) &IF(N_LISTS=5,"",I_S&INDEX(T_L6[],HELP!L284,1))))))),"")
P289: =IFERROR(IF(HELP!$F285>N,"",INDEX(T_L1[],HELP!G285,1) &IF(N_LISTS=1,"",I_S&INDEX(T_L2[],HELP!H285,1) &IF(N_LISTS=2,"",I_S&INDEX(T_L3[],HELP!I285,1) &IF(N_LISTS=3,"",I_S&INDEX(T_L4[],HELP!J285,1) &IF(N_LISTS=4,"",I_S&INDEX(T_L5[],HELP!K285,1) &IF(N_LISTS=5,"",I_S&INDEX(T_L6[],HELP!L285,1))))))),"")
P290: =IFERROR(IF(HELP!$F286>N,"",INDEX(T_L1[],HELP!G286,1) &IF(N_LISTS=1,"",I_S&INDEX(T_L2[],HELP!H286,1) &IF(N_LISTS=2,"",I_S&INDEX(T_L3[],HELP!I286,1) &IF(N_LISTS=3,"",I_S&INDEX(T_L4[],HELP!J286,1) &IF(N_LISTS=4,"",I_S&INDEX(T_L5[],HELP!K286,1) &IF(N_LISTS=5,"",I_S&INDEX(T_L6[],HELP!L286,1))))))),"")
P291: =IFERROR(IF(HELP!$F287>N,"",INDEX(T_L1[],HELP!G287,1) &IF(N_LISTS=1,"",I_S&INDEX(T_L2[],HELP!H287,1) &IF(N_LISTS=2,"",I_S&INDEX(T_L3[],HELP!I287,1) &IF(N_LISTS=3,"",I_S&INDEX(T_L4[],HELP!J287,1) &IF(N_LISTS=4,"",I_S&INDEX(T_L5[],HELP!K287,1) &IF(N_LISTS=5,"",I_S&INDEX(T_L6[],HELP!L287,1))))))),"")
P292: =IFERROR(IF(HELP!$F288>N,"",INDEX(T_L1[],HELP!G288,1) &IF(N_LISTS=1,"",I_S&INDEX(T_L2[],HELP!H288,1) &IF(N_LISTS=2,"",I_S&INDEX(T_L3[],HELP!I288,1) &IF(N_LISTS=3,"",I_S&INDEX(T_L4[],HELP!J288,1) &IF(N_LISTS=4,"",I_S&INDEX(T_L5[],HELP!K288,1) &IF(N_LISTS=5,"",I_S&INDEX(T_L6[],HELP!L288,1))))))),"")
...

Sheet Sheet1
A1: =IFERROR(IF(HELP!#REF!>N,"",INDEX(T_L1[],HELP!#REF!,1) &IF(N_LISTS=1,"",I_S&INDEX(T_L2[],HELP!#REF!,1) &IF(N_LISTS=2,"",I_S&INDEX(T_L3[],HELP!#REF!,1) &IF(N_LISTS=3,"",I_S&INDEX(T_L4[],HELP!#REF!,1) &IF(N_LISTS=4,"",I_S&INDEX(T_L5[],HELP!#REF!,1) &IF(N_LISTS=5,"",I_S&INDEX(T_L6[],HELP!#REF!,1))))))),"")
A2: =IFERROR(IF(HELP!#REF!>N,"",INDEX(T_L1[],HELP!#REF!,1) &IF(N_LISTS=1,"",I_S&INDEX(T_L2[],HELP!#REF!,1) &IF(N_LISTS=2,"",I_S&INDEX(T_L3[],HELP!#REF!,1) &IF(N_LISTS=3,"",I_S&INDEX(T_L4[],HELP!#REF!,1) &IF(N_LISTS=4,"",I_S&INDEX(T_L5[],HELP!#REF!,1) &IF(N_LISTS=5,"",I_S&INDEX(T_L6[],HELP!#REF!,1))))))),"") | B2: Banana Blueberries Blueberries Oats
A3: =IFERROR(IF(HELP!#REF!>N,"",INDEX(T_L1[],HELP!#REF!,1) &IF(N_LISTS=1,"",I_S&INDEX(T_L2[],HELP!#REF!,1) &IF(N_LISTS=2,"",I_S&INDEX(T_L3[],HELP!#REF!,1) &IF(N_LISTS=3,"",I_S&INDEX(T_L4[],HELP!#REF!,1) &IF(N_LISTS=4,"",I_S&INDEX(T_L5[],HELP!#REF!,1) &IF(N_LISTS=5,"",I_S&INDEX(T_L6[],HELP!#REF!,1))))))),"") | B3: Banana Blueberries Blueberries Honey
A4: =IFERROR(IF(HELP!#REF!>N,"",INDEX(T_L1[],HELP!#REF!,1) &IF(N_LISTS=1,"",I_S&INDEX(T_L2[],HELP!#REF!,1) &IF(N_LISTS=2,"",I_S&INDEX(T_L3[],HELP!#REF!,1) &IF(N_LISTS=3,"",I_S&INDEX(T_L4[],HELP!#REF!,1) &IF(N_LISTS=4,"",I_S&INDEX(T_L5[],HELP!#REF!,1) &IF(N_LISTS=5,"",I_S&INDEX(T_L6[],HELP!#REF!,1))))))),"") | B4: Banana Blueberries Blueberries Dates
A5: =IFERROR(IF(HELP!$F1>N,"",INDEX(T_L1[],HELP!#REF!,1) &IF(N_LISTS=1,"",I_S&INDEX(T_L2[],HELP!#REF!,1) &IF(N_LISTS=2,"",I_S&INDEX(T_L3[],HELP!#REF!,1) &IF(N_LISTS=3,"",I_S&INDEX(T_L4[],HELP!#REF!,1) &IF(N_LISTS=4,"",I_S&INDEX(T_L5[],HELP!#REF!,1) &IF(N_LISTS=5,"",I_S&INDEX(T_L6[],HELP!#REF!,1))))))),"") | B5: Banana Blueberries Blueberries Maple Syrup
A6: =IFERROR(IF(HELP!$F2>N,"",INDEX(T_L1[],HELP!#REF!,1) &IF(N_LISTS=1,"",I_S&INDEX(T_L2[],HELP!#REF!,1) &IF(N_LISTS=2,"",I_S&INDEX(T_L3[],HELP!#REF!,1) &IF(N_LISTS=3,"",I_S&INDEX(T_L4[],HELP!#REF!,1) &IF(N_LISTS=4,"",I_S&INDEX(T_L5[],HELP!#REF!,1) &IF(N_LISTS=5,"",I_S&INDEX(T_L6[],HELP!#REF!,1))))))),"") | B6: Banana Blueberries Blueberries Granola
A7: =IFERROR(IF(HELP!$F3>N,"",INDEX(T_L1[],HELP!#REF!,1) &IF(N_LISTS=1,"",I_S&INDEX(T_L2[],HELP!#REF!,1) &IF(N_LISTS=2,"",I_S&INDEX(T_L3[],HELP!#REF!,1) &IF(N_LISTS=3,"",I_S&INDEX(T_L4[],HELP!#REF!,1) &IF(N_LISTS=4,"",I_S&INDEX(T_L5[],HELP!#REF!,1) &IF(N_LISTS=5,"",I_S&INDEX(T_L6[],HELP!#REF!,1))))))),"") | B7: Banana Blueberries Strawberries Oats
A8: =IFERROR(IF(HELP!$F4>N,"",INDEX(T_L1[],HELP!#REF!,1) &IF(N_LISTS=1,"",I_S&INDEX(T_L2[],HELP!#REF!,1) &IF(N_LISTS=2,"",I_S&INDEX(T_L3[],HELP!#REF!,1) &IF(N_LISTS=3,"",I_S&INDEX(T_L4[],HELP!#REF!,1) &IF(N_LISTS=4,"",I_S&INDEX(T_L5[],HELP!#REF!,1) &IF(N_LISTS=5,"",I_S&INDEX(T_L6[],HELP!#REF!,1))))))),"") | B8: Banana Blueberries Strawberries Honey
A9: =IFERROR(IF(HELP!$F5>N,"",INDEX(T_L1[],HELP!#REF!,1) &IF(N_LISTS=1,"",I_S&INDEX(T_L2[],HELP!#REF!,1) &IF(N_LISTS=2,"",I_S&INDEX(T_L3[],HELP!#REF!,1) &IF(N_LISTS=3,"",I_S&INDEX(T_L4[],HELP!#REF!,1) &IF(N_LISTS=4,"",I_S&INDEX(T_L5[],HELP!#REF!,1) &IF(N_LISTS=5,"",I_S&INDEX(T_L6[],HELP!#REF!,1))))))),"") | B9: Banana Blueberries Strawberries Dates
A10: =IFERROR(IF(HELP!$F6>N,"",INDEX(T_L1[],HELP!#REF!,1) &IF(N_LISTS=1,"",I_S&INDEX(T_L2[],HELP!#REF!,1) &IF(N_LISTS=2,"",I_S&INDEX(T_L3[],HELP!#REF!,1) &IF(N_LISTS=3,"",I_S&INDEX(T_L4[],HELP!#REF!,1) &IF(N_LISTS=4,"",I_S&INDEX(T_L5[],HELP!#REF!,1) &IF(N_LISTS=5,"",I_S&INDEX(T_L6[],HELP!#REF!,1))))))),"") | B10: Banana Blueberries Strawberries Maple Syrup
A11: =IFERROR(IF(HELP!$F7>N,"",INDEX(T_L1[],HELP!#REF!,1) &IF(N_LISTS=1,"",I_S&INDEX(T_L2[],HELP!#REF!,1) &IF(N_LISTS=2,"",I_S&INDEX(T_L3[],HELP!#REF!,1) &IF(N_LISTS=3,"",I_S&INDEX(T_L4[],HELP!#REF!,1) &IF(N_LISTS=4,"",I_S&INDEX(T_L5[],HELP!#REF!,1) &IF(N_LISTS=5,"",I_S&INDEX(T_L6[],HELP!#REF!,1))))))),"") | B11: Banana Blueberries Strawberries Granola
A12: =IFERROR(IF(HELP!$F8>N,"",INDEX(T_L1[],HELP!#REF!,1) &IF(N_LISTS=1,"",I_S&INDEX(T_L2[],HELP!#REF!,1) &IF(N_LISTS=2,"",I_S&INDEX(T_L3[],HELP!#REF!,1) &IF(N_LISTS=3,"",I_S&INDEX(T_L4[],HELP!#REF!,1) &IF(N_LISTS=4,"",I_S&INDEX(T_L5[],HELP!#REF!,1) &IF(N_LISTS=5,"",I_S&INDEX(T_L6[],HELP!#REF!,1))))))),"") | B12: Banana Blueberries Mango Oats
A13: =IFERROR(IF(HELP!$F9>N,"",INDEX(T_L1[],HELP!#REF!,1) &IF(N_LISTS=1,"",I_S&INDEX(T_L2[],HELP!#REF!,1) &IF(N_LISTS=2,"",I_S&INDEX(T_L3[],HELP!#REF!,1) &IF(N_LISTS=3,"",I_S&INDEX(T_L4[],HELP!#REF!,1) &IF(N_LISTS=4,"",I_S&INDEX(T_L5[],HELP!#REF!,1) &IF(N_LISTS=5,"",I_S&INDEX(T_L6[],HELP!#REF!,1))))))),"") | B13: Banana Blueberries Mango Honey
A14: =IFERROR(IF(HELP!$F10>N,"",INDEX(T_L1[],HELP!#REF!,1) &IF(N_LISTS=1,"",I_S&INDEX(T_L2[],HELP!#REF!,1) &IF(N_LISTS=2,"",I_S&INDEX(T_L3[],HELP!#REF!,1) &IF(N_LISTS=3,"",I_S&INDEX(T_L4[],HELP!#REF!,1) &IF(N_LISTS=4,"",I_S&INDEX(T_L5[],HELP!#REF!,1) &IF(N_LISTS=5,"",I_S&INDEX(T_L6[],HELP!#REF!,1))))))),"") | B14: Banana Blueberries Mango Dates
A15: =IFERROR(IF(HELP!$F11>N,"",INDEX(T_L1[],HELP!#REF!,1) &IF(N_LISTS=1,"",I_S&INDEX(T_L2[],HELP!#REF!,1) &IF(N_LISTS=2,"",I_S&INDEX(T_L3[],HELP!#REF!,1) &IF(N_LISTS=3,"",I_S&INDEX(T_L4[],HELP!#REF!,1) &IF(N_LISTS=4,"",I_S&INDEX(T_L5[],HELP!#REF!,1) &IF(N_LISTS=5,"",I_S&INDEX(T_L6[],HELP!#REF!,1))))))),"") | B15: Banana Blueberries Mango Maple Syrup
A16: =IFERROR(IF(HELP!$F12>N,"",INDEX(T_L1[],HELP!#REF!,1) &IF(N_LISTS=1,"",I_S&INDEX(T_L2[],HELP!#REF!,1) &IF(N_LISTS=2,"",I_S&INDEX(T_L3[],HELP!#REF!,1) &IF(N_LISTS=3,"",I_S&INDEX(T_L4[],HELP!#REF!,1) &IF(N_LISTS=4,"",I_S&INDEX(T_L5[],HELP!#REF!,1) &IF(N_LISTS=5,"",I_S&INDEX(T_L6[],HELP!#REF!,1))))))),"") | B16: Banana Blueberries Mango Granola
... A27: =IFERROR(IF(HELP!$F23>N,"",INDEX(T_L1[],HELP!#REF!,1) &IF(N_LISTS=1,"",I_S&INDEX(T_L2[],HELP!#REF!,1) &IF(N_LISTS=2,"",I_S&INDEX(T_L3[],HELP!#REF!,1) &IF(N_LISTS=3,"",I_S&INDEX(T_L4[],HELP!#REF!,1) &IF(N_LISTS=4,"",I_S&INDEX(T_L5[],HELP!#REF!,1) &IF(N_LISTS=5,"",I_S&INDEX(T_L6[],HELP!#REF!,1))))))),"") | B27: Banana Blueberries Apple Oats
B28: Banana Blueberries Apple Honey
B29: Banana Blueberries Apple Dates
B30: Banana Blueberries Apple Maple Syrup
B31: Banana Blueberries Apple Granola
B32: Banana Blueberries Dates Oats
B33: Banana Blueberries Dates Honey
B34: Banana Blueberries Dates Dates
B35: Banana Blueberries Dates Maple Syrup
B36: Banana Blueberries Dates Granola
B37: Banana Blueberries Honey Oats
B38: Banana Blueberries Honey Honey
B39: Banana Blueberries Honey Dates
... B1037: Strawberries Pineapple Pineapple Banana

Sheet HELP
G1: ROW NUMBERS | O1: VALUES
F2: Combination # | G2: 1 | H2: 2 | I2: 3 | J2: 4 | K2: 5 | L2: 6 | O2: L1 | P2: L2 | Q2: L3 | R2: L4 | S2: L5 | T2: L6
A3: LIST | B3: Value counts | C3: Repeat After | F3: 1 | G3: =IF(OR($F3>N,G$2>N_LISTS),"",QUOTIENT($F3-(QUOTIENT($F3,N)*N),N_1) +IF(MOD($F3-(QUOTIENT($F3,N)*N),N_1)=0,0,1) +IF(MOD($F3,N)=0,C_L1,0)) -> 1 | H3: =IF(OR($F3>N,H$2>N_LISTS),"",QUOTIENT($F3-(QUOTIENT($F3,N_1)*N_1),N_2) +IF(MOD($F3-(QUOTIENT($F3,N_1)*N_1),N_2)=0,0,1) +IF(MOD($F3,N_1)=0,C_L2,0)) -> 1 | I3: =IF(OR($F3>N,I$2>N_LISTS),"",QUOTIENT($F3-(QUOTIENT($F3,N_2)*N_2),N_3) +IF(MOD($F3-(QUOTIENT($F3,N_2)*N_2),N_3)=0,0,1) +IF(MOD($F3,N_2)=0,C_L3,0)) | J3: =IF(OR($F3>N,J$2>N_LISTS),"",QUOTIENT($F3-(QUOTIENT($F3,N_3)*N_3),N_4) +IF(MOD($F3-(QUOTIENT($F3,N_3)*N_3),N_4)=0,0,1) +IF(MOD($F3,N_3)=0,C_L4,0)) | K3: =IF(OR($F3>N,K$2>N_LISTS),"",QUOTIENT($F3-(QUOTIENT($F3,N_4)*N_4),N_5) +IF(MOD($F3-(QUOTIENT($F3,N_4)*N_4),N_5)=0,0,1) +IF(MOD($F3,N_4)=0,C_L5,0)) | L3: =IF(OR($F3>N,L$2>N_LISTS),"",QUOTIENT($F3-(QUOTIENT($F3,N_5)*N_5),1) +IF(MOD($F3-(QUOTIENT($F3,N_5)*N_5),1)=0,0,1) +IF(MOD($F3,N_5)=0,C_L6,0)) | O3: =INDEX(T_L1[],G3) -> Peanut Butter, | P3: =INDEX(T_L2[],H3) -> Peanut Butter | Q3: =INDEX(T_L3[],I3) -> #VALUE! | R3: =INDEX(T_L4[],J3) -> #VALUE! | S3: =INDEX(T_L5[],K3) -> #VALUE! | T3: =INDEX(T_L6[],L3) -> #VALUE! | X3: VALIDATIONS
A4: 1 | B4: =COUNTA(T_L1[LIST 1]) -> 14 | C4: =IFERROR(IF(N_LISTS=0,0,IF(A4=N_LISTS+1,1,PRODUCT(OFFSET(B4,0,0,N_LISTS-A4+1)))),"") -> 210 | D4: N | F4: 2 | G4: =IF(OR($F4>N,G$2>N_LISTS),"",QUOTIENT($F4-(QUOTIENT($F4,N)*N),N_1) +IF(MOD($F4-(QUOTIENT($F4,N)*N),N_1)=0,0,1) +IF(MOD($F4,N)=0,C_L1,0)) -> 1 | H4: =IF(OR($F4>N,H$2>N_LISTS),"",QUOTIENT($F4-(QUOTIENT($F4,N_1)*N_1),N_2) +IF(MOD($F4-(QUOTIENT($F4,N_1)*N_1),N_2)=0,0,1) +IF(MOD($F4,N_1)=0,C_L2,0)) -> 2 | I4: =IF(OR($F4>N,I$2>N_LISTS),"",QUOTIENT($F4-(QUOTIENT($F4,N_2)*N_2),N_3) +IF(MOD($F4-(QUOTIENT($F4,N_2)*N_2),N_3)=0,0,1) +IF(MOD($F4,N_2)=0,C_L3,0)) | J4: =IF(OR($F4>N,J$2>N_LISTS),"",QUOTIENT($F4-(QUOTIENT($F4,N_3)*N_3),N_4) +IF(MOD($F4-(QUOTIENT($F4,N_3)*N_3),N_4)=0,0,1) +IF(MOD($F4,N_3)=0,C_L4,0)) | K4: =IF(OR($F4>N,K$2>N_LISTS),"",QUOTIENT($F4-(QUOTIENT($F4,N_4)*N_4),N_5) +IF(MOD($F4-(QUOTIENT($F4,N_4)*N_4),N_5)=0,0,1) +IF(MOD($F4,N_4)=0,C_L5,0)) | L4: =IF(OR($F4>N,L$2>N_LISTS),"",QUOTIENT($F4-(QUOTIENT($F4,N_5)*N_5),1) +IF(MOD($F4-(QUOTIENT($F4,N_5)*N_5),1)=0,0,1) +IF(MOD($F4,N_5)=0,C_L6,0)) | O4: =INDEX(T_L1[],G4) -> Peanut Butter, | P4: =INDEX(T_L2[],H4) -> Almond Butter | Q4: =INDEX(T_L3[],I4) -> #VALUE! | R4: =INDEX(T_L4[],J4) -> #VALUE! | S4: =INDEX(T_L5[],K4) -> #VALUE! | T4: =INDEX(T_L6[],L4) -> #VALUE! | X4: 1 | Y4: =COUNTIF(HELP!$G$3:$G$502,X4) -> 15 | Z4: =COUNTIF(HELP!$H$3:$H$502,X4) -> 14 | AA4: =COUNTIF(HELP!$I$3:$I$502,X4) -> 0 | AB4: =COUNTIF(HELP!$J$3:$J$502,X4) -> 0 | AC4: =COUNTIF(HELP!$K$3:$K$502,X4) -> 0 | AD4: =COUNTIF(HELP!$L$3:$L$502,X4) -> 0
A5: 2 | B5: =COUNTA(T_L2[LIST 2]) -> 15 | C5: =IFERROR(IF(N_LISTS=0,0,IF(A5=N_LISTS+1,1,PRODUCT(OFFSET(B5,0,0,N_LISTS-A5+1)))),"") -> 15 | D5: N_1 | F5: 3 | G5: =IF(OR($F5>N,G$2>N_LISTS),"",QUOTIENT($F5-(QUOTIENT($F5,N)*N),N_1) +IF(MOD($F5-(QUOTIENT($F5,N)*N),N_1)=0,0,1) +IF(MOD($F5,N)=0,C_L1,0)) -> 1 | H5: =IF(OR($F5>N,H$2>N_LISTS),"",QUOTIENT($F5-(QUOTIENT($F5,N_1)*N_1),N_2) +IF(MOD($F5-(QUOTIENT($F5,N_1)*N_1),N_2)=0,0,1) +IF(MOD($F5,N_1)=0,C_L2,0)) -> 3 | I5: =IF(OR($F5>N,I$2>N_LISTS),"",QUOTIENT($F5-(QUOTIENT($F5,N_2)*N_2),N_3) +IF(MOD($F5-(QUOTIENT($F5,N_2)*N_2),N_3)=0,0,1) +IF(MOD($F5,N_2)=0,C_L3,0)) | J5: =IF(OR($F5>N,J$2>N_LISTS),"",QUOTIENT($F5-(QUOTIENT($F5,N_3)*N_3),N_4) +IF(MOD($F5-(QUOTIENT($F5,N_3)*N_3),N_4)=0,0,1) +IF(MOD($F5,N_3)=0,C_L4,0)) | K5: =IF(OR($F5>N,K$2>N_LISTS),"",QUOTIENT($F5-(QUOTIENT($F5,N_4)*N_4),N_5) +IF(MOD($F5-(QUOTIENT($F5,N_4)*N_4),N_5)=0,0,1) +IF(MOD($F5,N_4)=0,C_L5,0)) | L5: =IF(OR($F5>N,L$2>N_LISTS),"",QUOTIENT($F5-(QUOTIENT($F5,N_5)*N_5),1) +IF(MOD($F5-(QUOTIENT($F5,N_5)*N_5),1)=0,0,1) +IF(MOD($F5,N_5)=0,C_L6,0)) | O5: =INDEX(T_L1[],G5) -> Peanut Butter, | P5: =INDEX(T_L2[],H5) -> Cashew Butter | Q5: =INDEX(T_L3[],I5) -> #VALUE! | R5: =INDEX(T_L4[],J5) -> #VALUE! | S5: =INDEX(T_L5[],K5) -> #VALUE! | T5: =INDEX(T_L6[],L5) -> #VALUE! | X5: 2 | Y5: =COUNTIF(HELP!$G$3:$G$502,X5) -> 15 | Z5: =COUNTIF(HELP!$H$3:$H$502,X5) -> 14 | AA5: =COUNTIF(HELP!$I$3:$I$502,X5) -> 0 | AB5: =COUNTIF(HELP!$J$3:$J$502,X5) -> 0 | AC5: =COUNTIF(HELP!$K$3:$K$502,X5) -> 0 | AD5: =COUNTIF(HELP!$L$3:$L$502,X5) -> 0
A6: 3 | B6: =COUNTA(T_L3[LIST 3]) -> 0 | C6: =IFERROR(IF(N_LISTS=0,0,IF(A6=N_LISTS+1,1,PRODUCT(OFFSET(B6,0,0,N_LISTS-A6+1)))),"") -> 1 | D6: N_2 | F6: 4 | G6: =IF(OR($F6>N,G$2>N_LISTS),"",QUOTIENT($F6-(QUOTIENT($F6,N)*N),N_1) +IF(MOD($F6-(QUOTIENT($F6,N)*N),N_1)=0,0,1) +IF(MOD($F6,N)=0,C_L1,0)) -> 1 | H6: =IF(OR($F6>N,H$2>N_LISTS),"",QUOTIENT($F6-(QUOTIENT($F6,N_1)*N_1),N_2) +IF(MOD($F6-(QUOTIENT($F6,N_1)*N_1),N_2)=0,0,1) +IF(MOD($F6,N_1)=0,C_L2,0)) -> 4 | I6: =IF(OR($F6>N,I$2>N_LISTS),"",QUOTIENT($F6-(QUOTIENT($F6,N_2)*N_2),N_3) +IF(MOD($F6-(QUOTIENT($F6,N_2)*N_2),N_3)=0,0,1) +IF(MOD($F6,N_2)=0,C_L3,0)) | J6: =IF(OR($F6>N,J$2>N_LISTS),"",QUOTIENT($F6-(QUOTIENT($F6,N_3)*N_3),N_4) +IF(MOD($F6-(QUOTIENT($F6,N_3)*N_3),N_4)=0,0,1) +IF(MOD($F6,N_3)=0,C_L4,0)) | K6: =IF(OR($F6>N,K$2>N_LISTS),"",QUOTIENT($F6-(QUOTIENT($F6,N_4)*N_4),N_5) +IF(MOD($F6-(QUOTIENT($F6,N_4)*N_4),N_5)=0,0,1) +IF(MOD($F6,N_4)=0,C_L5,0)) | L6: =IF(OR($F6>N,L$2>N_LISTS),"",QUOTIENT($F6-(QUOTIENT($F6,N_5)*N_5),1) +IF(MOD($F6-(QUOTIENT($F6,N_5)*N_5),1)=0,0,1) +IF(MOD($F6,N_5)=0,C_L6,0)) | O6: =INDEX(T_L1[],G6) -> Peanut Butter, | P6: =INDEX(T_L2[],H6) -> Chia Seeds | Q6: =INDEX(T_L3[],I6) -> #VALUE! | R6: =INDEX(T_L4[],J6) -> #VALUE! | S6: =INDEX(T_L5[],K6) -> #VALUE! | T6: =INDEX(T_L6[],L6) -> #VALUE! | X6: 3 | Y6: =COUNTIF(HELP!$G$3:$G$502,X6) -> 15 | Z6: =COUNTIF(HELP!$H$3:$H$502,X6) -> 14 | AA6: =COUNTIF(HELP!$I$3:$I$502,X6) -> 0 | AB6: =COUNTIF(HELP!$J$3:$J$502,X6) -> 0 | AC6: =COUNTIF(HELP!$K$3:$K$502,X6) -> 0 | AD6: =COUNTIF(HELP!$L$3:$L$502,X6) -> 0
A7: 4 | B7: =COUNTA(T_L4[LIST 4]) -> 0 | C7: =IFERROR(IF(N_LISTS=0,0,IF(A7=N_LISTS+1,1,PRODUCT(OFFSET(B7,0,0,N_LISTS-A7+1)))),"") -> 0 | D7: N_3 | F7: 5 | G7: =IF(OR($F7>N,G$2>N_LISTS),"",QUOTIENT($F7-(QUOTIENT($F7,N)*N),N_1) +IF(MOD($F7-(QUOTIENT($F7,N)*N),N_1)=0,0,1) +IF(MOD($F7,N)=0,C_L1,0)) -> 1 | H7: =IF(OR($F7>N,H$2>N_LISTS),"",QUOTIENT($F7-(QUOTIENT($F7,N_1)*N_1),N_2) +IF(MOD($F7-(QUOTIENT($F7,N_1)*N_1),N_2)=0,0,1) +IF(MOD($F7,N_1)=0,C_L2,0)) -> 5 | I7: =IF(OR($F7>N,I$2>N_LISTS),"",QUOTIENT($F7-(QUOTIENT($F7,N_2)*N_2),N_3) +IF(MOD($F7-(QUOTIENT($F7,N_2)*N_2),N_3)=0,0,1) +IF(MOD($F7,N_2)=0,C_L3,0)) | J7: =IF(OR($F7>N,J$2>N_LISTS),"",QUOTIENT($F7-(QUOTIENT($F7,N_3)*N_3),N_4) +IF(MOD($F7-(QUOTIENT($F7,N_3)*N_3),N_4)=0,0,1) +IF(MOD($F7,N_3)=0,C_L4,0)) | K7: =IF(OR($F7>N,K$2>N_LISTS),"",QUOTIENT($F7-(QUOTIENT($F7,N_4)*N_4),N_5) +IF(MOD($F7-(QUOTIENT($F7,N_4)*N_4),N_5)=0,0,1) +IF(MOD($F7,N_4)=0,C_L5,0)) | L7: =IF(OR($F7>N,L$2>N_LISTS),"",QUOTIENT($F7-(QUOTIENT($F7,N_5)*N_5),1) +IF(MOD($F7-(QUOTIENT($F7,N_5)*N_5),1)=0,0,1) +IF(MOD($F7,N_5)=0,C_L6,0)) | O7: =INDEX(T_L1[],G7) -> Peanut Butter, | P7: =INDEX(T_L2[],H7) -> Flax Seeds | Q7: =INDEX(T_L3[],I7) -> #VALUE! | R7: =INDEX(T_L4[],J7) -> #VALUE! | S7: =INDEX(T_L5[],K7) -> #VALUE! | T7: =INDEX(T_L6[],L7) -> #VALUE! | X7: 4 | Y7: =COUNTIF(HELP!$G$3:$G$502,X7) -> 15 | Z7: =COUNTIF(HELP!$H$3:$H$502,X7) -> 14 | AA7: =COUNTIF(HELP!$I$3:$I$502,X7) -> 0 | AB7: =COUNTIF(HELP!$J$3:$J$502,X7) -> 0 | AC7: =COUNTIF(HELP!$K$3:$K$502,X7) -> 0 | AD7: =COUNTIF(HELP!$L$3:$L$502,X7) -> 0
A8: 5 | B8: =COUNTA(T_L5[LIST 5]) -> 0 | C8: =IFERROR(IF(N_LISTS=0,0,IF(A8=N_LISTS+1,1,PRODUCT(OFFSET(B8,0,0,N_LISTS-A8+1)))),"") -> 0 | D8: N_4 | F8: 6 | G8: =IF(OR($F8>N,G$2>N_LISTS),"",QUOTIENT($F8-(QUOTIENT($F8,N)*N),N_1) +IF(MOD($F8-(QUOTIENT($F8,N)*N),N_1)=0,0,1) +IF(MOD($F8,N)=0,C_L1,0)) -> 1 | H8: =IF(OR($F8>N,H$2>N_LISTS),"",QUOTIENT($F8-(QUOTIENT($F8,N_1)*N_1),N_2) +IF(MOD($F8-(QUOTIENT($F8,N_1)*N_1),N_2)=0,0,1) +IF(MOD($F8,N_1)=0,C_L2,0)) -> 6 | I8: =IF(OR($F8>N,I$2>N_LISTS),"",QUOTIENT($F8-(QUOTIENT($F8,N_2)*N_2),N_3) +IF(MOD($F8-(QUOTIENT($F8,N_2)*N_2),N_3)=0,0,1) +IF(MOD($F8,N_2)=0,C_L3,0)) | J8: =IF(OR($F8>N,J$2>N_LISTS),"",QUOTIENT($F8-(QUOTIENT($F8,N_3)*N_3),N_4) +IF(MOD($F8-(QUOTIENT($F8,N_3)*N_3),N_4)=0,0,1) +IF(MOD($F8,N_3)=0,C_L4,0)) | K8: =IF(OR($F8>N,K$2>N_LISTS),"",QUOTIENT($F8-(QUOTIENT($F8,N_4)*N_4),N_5) +IF(MOD($F8-(QUOTIENT($F8,N_4)*N_4),N_5)=0,0,1) +IF(MOD($F8,N_4)=0,C_L5,0)) | L8: =IF(OR($F8>N,L$2>N_LISTS),"",QUOTIENT($F8-(QUOTIENT($F8,N_5)*N_5),1) +IF(MOD($F8-(QUOTIENT($F8,N_5)*N_5),1)=0,0,1) +IF(MOD($F8,N_5)=0,C_L6,0)) | O8: =INDEX(T_L1[],G8) -> Peanut Butter, | P8: =INDEX(T_L2[],H8) -> Hemp Seeds | Q8: =INDEX(T_L3[],I8) -> #VALUE! | R8: =INDEX(T_L4[],J8) -> #VALUE! | S8: =INDEX(T_L5[],K8) -> #VALUE! | T8: =INDEX(T_L6[],L8) -> #VALUE! | X8: 5 | Y8: =COUNTIF(HELP!$G$3:$G$502,X8) -> 15 | Z8: =COUNTIF(HELP!$H$3:$H$502,X8) -> 14 | AA8: =COUNTIF(HELP!$I$3:$I$502,X8) -> 0 | AB8: =COUNTIF(HELP!$J$3:$J$502,X8) -> 0 | AC8: =COUNTIF(HELP!$K$3:$K$502,X8) -> 0 | AD8: =COUNTIF(HELP!$L$3:$L$502,X8) -> 0
A9: 6 | B9: =COUNTA(T_L6[LIST 6]) -> 0 | C9: =IFERROR(IF(N_LISTS=0,0,IF(A9=N_LISTS+1,1,PRODUCT(OFFSET(B9,0,0,N_LISTS-A9+1)))),"") -> 0 | D9: N_5 | F9: 7 | G9: =IF(OR($F9>N,G$2>N_LISTS),"",QUOTIENT($F9-(QUOTIENT($F9,N)*N),N_1) +IF(MOD($F9-(QUOTIENT($F9,N)*N),N_1)=0,0,1) +IF(MOD($F9,N)=0,C_L1,0)) -> 1 | H9: =IF(OR($F9>N,H$2>N_LISTS),"",QUOTIENT($F9-(QUOTIENT($F9,N_1)*N_1),N_2) +IF(MOD($F9-(QUOTIENT($F9,N_1)*N_1),N_2)=0,0,1) +IF(MOD($F9,N_1)=0,C_L2,0)) -> 7 | I9: =IF(OR($F9>N,I$2>N_LISTS),"",QUOTIENT($F9-(QUOTIENT($F9,N_2)*N_2),N_3) +IF(MOD($F9-(QUOTIENT($F9,N_2)*N_2),N_3)=0,0,1) +IF(MOD($F9,N_2)=0,C_L3,0)) | J9: =IF(OR($F9>N,J$2>N_LISTS),"",QUOTIENT($F9-(QUOTIENT($F9,N_3)*N_3),N_4) +IF(MOD($F9-(QUOTIENT($F9,N_3)*N_3),N_4)=0,0,1) +IF(MOD($F9,N_3)=0,C_L4,0)) | K9: =IF(OR($F9>N,K$2>N_LISTS),"",QUOTIENT($F9-(QUOTIENT($F9,N_4)*N_4),N_5) +IF(MOD($F9-(QUOTIENT($F9,N_4)*N_4),N_5)=0,0,1) +IF(MOD($F9,N_4)=0,C_L5,0)) | L9: =IF(OR($F9>N,L$2>N_LISTS),"",QUOTIENT($F9-(QUOTIENT($F9,N_5)*N_5),1) +IF(MOD($F9-(QUOTIENT($F9,N_5)*N_5),1)=0,0,1) +IF(MOD($F9,N_5)=0,C_L6,0)) | O9: =INDEX(T_L1[],G9) -> Peanut Butter, | P9: =INDEX(T_L2[],H9) -> Avocado | Q9: =INDEX(T_L3[],I9) -> #VALUE! | R9: =INDEX(T_L4[],J9) -> #VALUE! | S9: =INDEX(T_L5[],K9) -> #VALUE! | T9: =INDEX(T_L6[],L9) -> #VALUE! | X9: 6 | Y9: =COUNTIF(HELP!$G$3:$G$502,X9) -> 15 | Z9: =COUNTIF(HELP!$H$3:$H$502,X9) -> 14 | AA9: =COUNTIF(HELP!$I$3:$I$502,X9) -> 0 | AB9: =COUNTIF(HELP!$J$3:$J$502,X9) -> 0 | AC9: =COUNTIF(HELP!$K$3:$K$502,X9) -> 0 | AD9: =COUNTIF(HELP!$L$3:$L$502,X9) -> 0
F10: 8 | G10: =IF(OR($F10>N,G$2>N_LISTS),"",QUOTIENT($F10-(QUOTIENT($F10,N)*N),N_1) +IF(MOD($F10-(QUOTIENT($F10,N)*N),N_1)=0,0,1) +IF(MOD($F10,N)=0,C_L1,0)) -> 1 | H10: =IF(OR($F10>N,H$2>N_LISTS),"",QUOTIENT($F10-(QUOTIENT($F10,N_1)*N_1),N_2) +IF(MOD($F10-(QUOTIENT($F10,N_1)*N_1),N_2)=0,0,1) +IF(MOD($F10,N_1)=0,C_L2,0)) -> 8 | I10: =IF(OR($F10>N,I$2>N_LISTS),"",QUOTIENT($F10-(QUOTIENT($F10,N_2)*N_2),N_3) +IF(MOD($F10-(QUOTIENT($F10,N_2)*N_2),N_3)=0,0,1) +IF(MOD($F10,N_2)=0,C_L3,0)) | J10: =IF(OR($F10>N,J$2>N_LISTS),"",QUOTIENT($F10-(QUOTIENT($F10,N_3)*N_3),N_4) +IF(MOD($F10-(QUOTIENT($F10,N_3)*N_3),N_4)=0,0,1) +IF(MOD($F10,N_3)=0,C_L4,0)) | K10: =IF(OR($F10>N,K$2>N_LISTS),"",QUOTIENT($F10-(QUOTIENT($F10,N_4)*N_4),N_5) +IF(MOD($F10-(QUOTIENT($F10,N_4)*N_4),N_5)=0,0,1) +IF(MOD($F10,N_4)=0,C_L5,0)) | L10: =IF(OR($F10>N,L$2>N_LISTS),"",QUOTIENT($F10-(QUOTIENT($F10,N_5)*N_5),1) +IF(MOD($F10-(QUOTIENT($F10,N_5)*N_5),1)=0,0,1) +IF(MOD($F10,N_5)=0,C_L6,0)) | O10: =INDEX(T_L1[],G10) -> Peanut Butter, | P10: =INDEX(T_L2[],H10) -> Coconut Oil | Q10: =INDEX(T_L3[],I10) -> #VALUE! | R10: =INDEX(T_L4[],J10) -> #VALUE! | S10: =INDEX(T_L5[],K10) -> #VALUE! | T10: =INDEX(T_L6[],L10) -> #VALUE! | X10: 7 | Y10: =COUNTIF(HELP!$G$3:$G$502,X10) -> 15 | Z10: =COUNTIF(HELP!$H$3:$H$502,X10) -> 14 | AA10: =COUNTIF(HELP!$I$3:$I$502,X10) -> 0 | AB10: =COUNTIF(HELP!$J$3:$J$502,X10) -> 0 | AC10: =COUNTIF(HELP!$K$3:$K$502,X10) -> 0 | AD10: =COUNTIF(HELP!$L$3:$L$502,X10) -> 0
A11: Valid Lists | B11: =IFERROR(MATCH(0,B4:B9,0)-1,6) -> 2 | F11: 9 | G11: =IF(OR($F11>N,G$2>N_LISTS),"",QUOTIENT($F11-(QUOTIENT($F11,N)*N),N_1) +IF(MOD($F11-(QUOTIENT($F11,N)*N),N_1)=0,0,1) +IF(MOD($F11,N)=0,C_L1,0)) -> 1 | H11: =IF(OR($F11>N,H$2>N_LISTS),"",QUOTIENT($F11-(QUOTIENT($F11,N_1)*N_1),N_2) +IF(MOD($F11-(QUOTIENT($F11,N_1)*N_1),N_2)=0,0,1) +IF(MOD($F11,N_1)=0,C_L2,0)) -> 9 | I11: =IF(OR($F11>N,I$2>N_LISTS),"",QUOTIENT($F11-(QUOTIENT($F11,N_2)*N_2),N_3) +IF(MOD($F11-(QUOTIENT($F11,N_2)*N_2),N_3)=0,0,1) +IF(MOD($F11,N_2)=0,C_L3,0)) | J11: =IF(OR($F11>N,J$2>N_LISTS),"",QUOTIENT($F11-(QUOTIENT($F11,N_3)*N_3),N_4) +IF(MOD($F11-(QUOTIENT($F11,N_3)*N_3),N_4)=0,0,1) +IF(MOD($F11,N_3)=0,C_L4,0)) | K11: =IF(OR($F11>N,K$2>N_LISTS),"",QUOTIENT($F11-(QUOTIENT($F11,N_4)*N_4),N_5) +IF(MOD($F11-(QUOTIENT($F11,N_4)*N_4),N_5)=0,0,1) +IF(MOD($F11,N_4)=0,C_L5,0)) | L11: =IF(OR($F11>N,L$2>N_LISTS),"",QUOTIENT($F11-(QUOTIENT($F11,N_5)*N_5),1) +IF(MOD($F11-(QUOTIENT($F11,N_5)*N_5),1)=0,0,1) +IF(MOD($F11,N_5)=0,C_L6,0)) | O11: =INDEX(T_L1[],G11) -> Peanut Butter, | P11: =INDEX(T_L2[],H11) -> MCT Oil | Q11: =INDEX(T_L3[],I11) -> #VALUE! | R11: =INDEX(T_L4[],J11) -> #VALUE! | S11: =INDEX(T_L5[],K11) -> #VALUE! | T11: =INDEX(T_L6[],L11) -> #VALUE! | X11: 8 | Y11: =COUNTIF(HELP!$G$3:$G$502,X11) -> 15 | Z11: =COUNTIF(HELP!$H$3:$H$502,X11) -> 14 | AA11: =COUNTIF(HELP!$I$3:$I$502,X11) -> 0 | AB11: =COUNTIF(HELP!$J$3:$J$502,X11) -> 0 | AC11: =COUNTIF(HELP!$K$3:$K$502,X11) -> 0 | AD11: =COUNTIF(HELP!$L$3:$L$502,X11) -> 0
F12: 10 | G12: =IF(OR($F12>N,G$2>N_LISTS),"",QUOTIENT($F12-(QUOTIENT($F12,N)*N),N_1) +IF(MOD($F12-(QUOTIENT($F12,N)*N),N_1)=0,0,1) +IF(MOD($F12,N)=0,C_L1,0)) -> 1 | H12: =IF(OR($F12>N,H$2>N_LISTS),"",QUOTIENT($F12-(QUOTIENT($F12,N_1)*N_1),N_2) +IF(MOD($F12-(QUOTIENT($F12,N_1)*N_1),N_2)=0,0,1) +IF(MOD($F12,N_1)=0,C_L2,0)) -> 10 | I12: =IF(OR($F12>N,I$2>N_LISTS),"",QUOTIENT($F12-(QUOTIENT($F12,N_2)*N_2),N_3) +IF(MOD($F12-(QUOTIENT($F12,N_2)*N_2),N_3)=0,0,1) +IF(MOD($F12,N_2)=0,C_L3,0)) | J12: =IF(OR($F12>N,J$2>N_LISTS),"",QUOTIENT($F12-(QUOTIENT($F12,N_3)*N_3),N_4) +IF(MOD($F12-(QUOTIENT($F12,N_3)*N_3),N_4)=0,0,1) +IF(MOD($F12,N_3)=0,C_L4,0)) | K12: =IF(OR($F12>N,K$2>N_LISTS),"",QUOTIENT($F12-(QUOTIENT($F12,N_4)*N_4),N_5) +IF(MOD($F12-(QUOTIENT($F12,N_4)*N_4),N_5)=0,0,1) +IF(MOD($F12,N_4)=0,C_L5,0)) | L12: =IF(OR($F12>N,L$2>N_LISTS),"",QUOTIENT($F12-(QUOTIENT($F12,N_5)*N_5),1) +IF(MOD($F12-(QUOTIENT($F12,N_5)*N_5),1)=0,0,1) +IF(MOD($F12,N_5)=0,C_L6,0)) | O12: =INDEX(T_L1[],G12) -> Peanut Butter, | P12: =INDEX(T_L2[],H12) -> Walnuts | Q12: =INDEX(T_L3[],I12) -> #VALUE! | R12: =INDEX(T_L4[],J12) -> #VALUE! | S12: =INDEX(T_L5[],K12) -> #VALUE! | T12: =INDEX(T_L6[],L12) -> #VALUE! | X12: 9 | Y12: =COUNTIF(HELP!$G$3:$G$502,X12) -> 15 | Z12: =COUNTIF(HELP!$H$3:$H$502,X12) -> 14 | AA12: =COUNTIF(HELP!$I$3:$I$502,X12) -> 0 | AB12: =COUNTIF(HELP!$J$3:$J$502,X12) -> 0 | AC12: =COUNTIF(HELP!$K$3:$K$502,X12) -> 0 | AD12: =COUNTIF(HELP!$L$3:$L$502,X12) -> 0
F13: 11 | G13: =IF(OR($F13>N,G$2>N_LISTS),"",QUOTIENT($F13-(QUOTIENT($F13,N)*N),N_1) +IF(MOD($F13-(QUOTIENT($F13,N)*N),N_1)=0,0,1) +IF(MOD($F13,N)=0,C_L1,0)) -> 1 | H13: =IF(OR($F13>N,H$2>N_LISTS),"",QUOTIENT($F13-(QUOTIENT($F13,N_1)*N_1),N_2) +IF(MOD($F13-(QUOTIENT($F13,N_1)*N_1),N_2)=0,0,1) +IF(MOD($F13,N_1)=0,C_L2,0)) -> 11 | I13: =IF(OR($F13>N,I$2>N_LISTS),"",QUOTIENT($F13-(QUOTIENT($F13,N_2)*N_2),N_3) +IF(MOD($F13-(QUOTIENT($F13,N_2)*N_2),N_3)=0,0,1) +IF(MOD($F13,N_2)=0,C_L3,0)) | J13: =IF(OR($F13>N,J$2>N_LISTS),"",QUOTIENT($F13-(QUOTIENT($F13,N_3)*N_3),N_4) +IF(MOD($F13-(QUOTIENT($F13,N_3)*N_3),N_4)=0,0,1) +IF(MOD($F13,N_3)=0,C_L4,0)) | K13: =IF(OR($F13>N,K$2>N_LISTS),"",QUOTIENT($F13-(QUOTIENT($F13,N_4)*N_4),N_5) +IF(MOD($F13-(QUOTIENT($F13,N_4)*N_4),N_5)=0,0,1) +IF(MOD($F13,N_4)=0,C_L5,0)) | L13: =IF(OR($F13>N,L$2>N_LISTS),"",QUOTIENT($F13-(QUOTIENT($F13,N_5)*N_5),1) +IF(MOD($F13-(QUOTIENT($F13,N_5)*N_5),1)=0,0,1) +IF(MOD($F13,N_5)=0,C_L6,0)) | O13: =INDEX(T_L1[],G13) -> Peanut Butter, | P13: =INDEX(T_L2[],H13) -> Pecans | Q13: =INDEX(T_L3[],I13) -> #VALUE! | R13: =INDEX(T_L4[],J13) -> #VALUE! | S13: =INDEX(T_L5[],K13) -> #VALUE! | T13: =INDEX(T_L6[],L13) -> #VALUE! | X13: 10 | Y13: =COUNTIF(HELP!$G$3:$G$502,X13) -> 15 | Z13: =COUNTIF(HELP!$H$3:$H$502,X13) -> 14 | AA13: =COUNTIF(HELP!$I$3:$I$502,X13) -> 0 | AB13: =COUNTIF(HELP!$J$3:$J$502,X13) -> 0 | AC13: =COUNTIF(HELP!$K$3:$K$502,X13) -> 0 | AD13: =COUNTIF(HELP!$L$3:$L$502,X13) -> 0
F14: 12 | G14: =IF(OR($F14>N,G$2>N_LISTS),"",QUOTIENT($F14-(QUOTIENT($F14,N)*N),N_1) +IF(MOD($F14-(QUOTIENT($F14,N)*N),N_1)=0,0,1) +IF(MOD($F14,N)=0,C_L1,0)) -> 1 | H14: =IF(OR($F14>N,H$2>N_LISTS),"",QUOTIENT($F14-(QUOTIENT($F14,N_1)*N_1),N_2) +IF(MOD($F14-(QUOTIENT($F14,N_1)*N_1),N_2)=0,0,1) +IF(MOD($F14,N_1)=0,C_L2,0)) -> 12 | I14: =IF(OR($F14>N,I$2>N_LISTS),"",QUOTIENT($F14-(QUOTIENT($F14,N_2)*N_2),N_3) +IF(MOD($F14-(QUOTIENT($F14,N_2)*N_2),N_3)=0,0,1) +IF(MOD($F14,N_2)=0,C_L3,0)) | J14: =IF(OR($F14>N,J$2>N_LISTS),"",QUOTIENT($F14-(QUOTIENT($F14,N_3)*N_3),N_4) +IF(MOD($F14-(QUOTIENT($F14,N_3)*N_3),N_4)=0,0,1) +IF(MOD($F14,N_3)=0,C_L4,0)) | K14: =IF(OR($F14>N,K$2>N_LISTS),"",QUOTIENT($F14-(QUOTIENT($F14,N_4)*N_4),N_5) +IF(MOD($F14-(QUOTIENT($F14,N_4)*N_4),N_5)=0,0,1) +IF(MOD($F14,N_4)=0,C_L5,0)) | L14: =IF(OR($F14>N,L$2>N_LISTS),"",QUOTIENT($F14-(QUOTIENT($F14,N_5)*N_5),1) +IF(MOD($F14-(QUOTIENT($F14,N_5)*N_5),1)=0,0,1) +IF(MOD($F14,N_5)=0,C_L6,0)) | O14: =INDEX(T_L1[],G14) -> Peanut Butter, | P14: =INDEX(T_L2[],H14) -> Macadamia Nuts | Q14: =INDEX(T_L3[],I14) -> #VALUE! | R14: =INDEX(T_L4[],J14) -> #VALUE! | S14: =INDEX(T_L5[],K14) -> #VALUE! | T14: =INDEX(T_L6[],L14) -> #VALUE! | X14: 11 | Y14: =COUNTIF(HELP!$G$3:$G$502,X14) -> 15 | Z14: =COUNTIF(HELP!$H$3:$H$502,X14) -> 14 | AA14: =COUNTIF(HELP!$I$3:$I$502,X14) -> 0 | AB14: =COUNTIF(HELP!$J$3:$J$502,X14) -> 0 | AC14: =COUNTIF(HELP!$K$3:$K$502,X14) -> 0 | AD14: =COUNTIF(HELP!$L$3:$L$502,X14) -> 0
F15: 13 | G15: =IF(OR($F15>N,G$2>N_LISTS),"",QUOTIENT($F15-(QUOTIENT($F15,N)*N),N_1) +IF(MOD($F15-(QUOTIENT($F15,N)*N),N_1)=0,0,1) +IF(MOD($F15,N)=0,C_L1,0)) -> 1 | H15: =IF(OR($F15>N,H$2>N_LISTS),"",QUOTIENT($F15-(QUOTIENT($F15,N_1)*N_1),N_2) +IF(MOD($F15-(QUOTIENT($F15,N_1)*N_1),N_2)=0,0,1) +IF(MOD($F15,N_1)=0,C_L2,0)) -> 13 | I15: =IF(OR($F15>N,I$2>N_LISTS),"",QUOTIENT($F15-(QUOTIENT($F15,N_2)*N_2),N_3) +IF(MOD($F15-(QUOTIENT($F15,N_2)*N_2),N_3)=0,0,1) +IF(MOD($F15,N_2)=0,C_L3,0)) | J15: =IF(OR($F15>N,J$2>N_LISTS),"",QUOTIENT($F15-(QUOTIENT($F15,N_3)*N_3),N_4) +IF(MOD($F15-(QUOTIENT($F15,N_3)*N_3),N_4)=0,0,1) +IF(MOD($F15,N_3)=0,C_L4,0)) | K15: =IF(OR($F15>N,K$2>N_LISTS),"",QUOTIENT($F15-(QUOTIENT($F15,N_4)*N_4),N_5) +IF(MOD($F15-(QUOTIENT($F15,N_4)*N_4),N_5)=0,0,1) +IF(MOD($F15,N_4)=0,C_L5,0)) | L15: =IF(OR($F15>N,L$2>N_LISTS),"",QUOTIENT($F15-(QUOTIENT($F15,N_5)*N_5),1) +IF(MOD($F15-(QUOTIENT($F15,N_5)*N_5),1)=0,0,1) +IF(MOD($F15,N_5)=0,C_L6,0)) | O15: =INDEX(T_L1[],G15) -> Peanut Butter, | P15: =INDEX(T_L2[],H15) -> Tahini | Q15: =INDEX(T_L3[],I15) -> #VALUE! | R15: =INDEX(T_L4[],J15) -> #VALUE! | S15: =INDEX(T_L5[],K15) -> #VALUE! | T15: =INDEX(T_L6[],L15) -> #VALUE! | X15: 12 | Y15: =COUNTIF(HELP!$G$3:$G$502,X15) -> 15 | Z15: =COUNTIF(HELP!$H$3:$H$502,X15) -> 14 | AA15: =COUNTIF(HELP!$I$3:$I$502,X15) -> 0 | AB15: =COUNTIF(HELP!$J$3:$J$502,X15) -> 0 | AC15: =COUNTIF(HELP!$K$3:$K$502,X15) -> 0 | AD15: =COUNTIF(HELP!$L$3:$L$502,X15) -> 0
F16: 14 | G16: =IF(OR($F16>N,G$2>N_LISTS),"",QUOTIENT($F16-(QUOTIENT($F16,N)*N),N_1) +IF(MOD($F16-(QUOTIENT($F16,N)*N),N_1)=0,0,1) +IF(MOD($F16,N)=0,C_L1,0)) -> 1 | H16: =IF(OR($F16>N,H$2>N_LISTS),"",QUOTIENT($F16-(QUOTIENT($F16,N_1)*N_1),N_2) +IF(MOD($F16-(QUOTIENT($F16,N_1)*N_1),N_2)=0,0,1) +IF(MOD($F16,N_1)=0,C_L2,0)) -> 14 | I16: =IF(OR($F16>N,I$2>N_LISTS),"",QUOTIENT($F16-(QUOTIENT($F16,N_2)*N_2),N_3) +IF(MOD($F16-(QUOTIENT($F16,N_2)*N_2),N_3)=0,0,1) +IF(MOD($F16,N_2)=0,C_L3,0)) | J16: =IF(OR($F16>N,J$2>N_LISTS),"",QUOTIENT($F16-(QUOTIENT($F16,N_3)*N_3),N_4) +IF(MOD($F16-(QUOTIENT($F16,N_3)*N_3),N_4)=0,0,1) +IF(MOD($F16,N_3)=0,C_L4,0)) | K16: =IF(OR($F16>N,K$2>N_LISTS),"",QUOTIENT($F16-(QUOTIENT($F16,N_4)*N_4),N_5) +IF(MOD($F16-(QUOTIENT($F16,N_4)*N_4),N_5)=0,0,1) +IF(MOD($F16,N_4)=0,C_L5,0)) | L16: =IF(OR($F16>N,L$2>N_LISTS),"",QUOTIENT($F16-(QUOTIENT($F16,N_5)*N_5),1) +IF(MOD($F16-(QUOTIENT($F16,N_5)*N_5),1)=0,0,1) +IF(MOD($F16,N_5)=0,C_L6,0)) | O16: =INDEX(T_L1[],G16) -> Peanut Butter, | P16: =INDEX(T_L2[],H16) -> Dark Chocolate | Q16: =INDEX(T_L3[],I16) -> #VALUE! | R16: =INDEX(T_L4[],J16) -> #VALUE! | S16: =INDEX(T_L5[],K16) -> #VALUE! | T16: =INDEX(T_L6[],L16) -> #VALUE! | X16: 13 | Y16: =COUNTIF(HELP!$G$3:$G$502,X16) -> 15 | Z16: =COUNTIF(HELP!$H$3:$H$502,X16) -> 14 | AA16: =COUNTIF(HELP!$I$3:$I$502,X16) -> 0 | AB16: =COUNTIF(HELP!$J$3:$J$502,X16) -> 0 | AC16: =COUNTIF(HELP!$K$3:$K$502,X16) -> 0 | AD16: =COUNTIF(HELP!$L$3:$L$502,X16) -> 0
F17: 15 | G17: =IF(OR($F17>N,G$2>N_LISTS),"",QUOTIENT($F17-(QUOTIENT($F17,N)*N),N_1) +IF(MOD($F17-(QUOTIENT($F17,N)*N),N_1)=0,0,1) +IF(MOD($F17,N)=0,C_L1,0)) -> 1 | H17: =IF(OR($F17>N,H$2>N_LISTS),"",QUOTIENT($F17-(QUOTIENT($F17,N_1)*N_1),N_2) +IF(MOD($F17-(QUOTIENT($F17,N_1)*N_1),N_2)=0,0,1) +IF(MOD($F17,N_1)=0,C_L2,0)) -> 15 | I17: =IF(OR($F17>N,I$2>N_LISTS),"",QUOTIENT($F17-(QUOTIENT($F17,N_2)*N_2),N_3) +IF(MOD($F17-(QUOTIENT($F17,N_2)*N_2),N_3)=0,0,1) +IF(MOD($F17,N_2)=0,C_L3,0)) | J17: =IF(OR($F17>N,J$2>N_LISTS),"",QUOTIENT($F17-(QUOTIENT($F17,N_3)*N_3),N_4) +IF(MOD($F17-(QUOTIENT($F17,N_3)*N_3),N_4)=0,0,1) +IF(MOD($F17,N_3)=0,C_L4,0)) | K17: =IF(OR($F17>N,K$2>N_LISTS),"",QUOTIENT($F17-(QUOTIENT($F17,N_4)*N_4),N_5) +IF(MOD($F17-(QUOTIENT($F17,N_4)*N_4),N_5)=0,0,1) +IF(MOD($F17,N_4)=0,C_L5,0)) | L17: =IF(OR($F17>N,L$2>N_LISTS),"",QUOTIENT($F17-(QUOTIENT($F17,N_5)*N_5),1) +IF(MOD($F17-(QUOTIENT($F17,N_5)*N_5),1)=0,0,1) +IF(MOD($F17,N_5)=0,C_L6,0)) | O17: =INDEX(T_L1[],G17) -> Peanut Butter, | P17: =INDEX(T_L2[],H17) -> - | Q17: =INDEX(T_L3[],I17) -> #VALUE! | R17: =INDEX(T_L4[],J17) -> #VALUE! | S17: =INDEX(T_L5[],K17) -> #VALUE! | T17: =INDEX(T_L6[],L17) -> #VALUE! | X17: 14 | Y17: =COUNTIF(HELP!$G$3:$G$502,X17) -> 15 | Z17: =COUNTIF(HELP!$H$3:$H$502,X17) -> 14 | AA17: =COUNTIF(HELP!$I$3:$I$502,X17) -> 0 | AB17: =COUNTIF(HELP!$J$3:$J$502,X17) -> 0 | AC17: =COUNTIF(HELP!$K$3:$K$502,X17) -> 0 | AD17: =COUNTIF(HELP!$L$3:$L$502,X17) -> 0
F18: 16 | G18: =IF(OR($F18>N,G$2>N_LISTS),"",QUOTIENT($F18-(QUOTIENT($F18,N)*N),N_1) +IF(MOD($F18-(QUOTIENT($F18,N)*N),N_1)=0,0,1) +IF(MOD($F18,N)=0,C_L1,0)) -> 2 | H18: =IF(OR($F18>N,H$2>N_LISTS),"",QUOTIENT($F18-(QUOTIENT($F18,N_1)*N_1),N_2) +IF(MOD($F18-(QUOTIENT($F18,N_1)*N_1),N_2)=0,0,1) +IF(MOD($F18,N_1)=0,C_L2,0)) -> 1 | I18: =IF(OR($F18>N,I$2>N_LISTS),"",QUOTIENT($F18-(QUOTIENT($F18,N_2)*N_2),N_3) +IF(MOD($F18-(QUOTIENT($F18,N_2)*N_2),N_3)=0,0,1) +IF(MOD($F18,N_2)=0,C_L3,0)) | J18: =IF(OR($F18>N,J$2>N_LISTS),"",QUOTIENT($F18-(QUOTIENT($F18,N_3)*N_3),N_4) +IF(MOD($F18-(QUOTIENT($F18,N_3)*N_3),N_4)=0,0,1) +IF(MOD($F18,N_3)=0,C_L4,0)) | K18: =IF(OR($F18>N,K$2>N_LISTS),"",QUOTIENT($F18-(QUOTIENT($F18,N_4)*N_4),N_5) +IF(MOD($F18-(QUOTIENT($F18,N_4)*N_4),N_5)=0,0,1) +IF(MOD($F18,N_4)=0,C_L5,0)) | L18: =IF(OR($F18>N,L$2>N_LISTS),"",QUOTIENT($F18-(QUOTIENT($F18,N_5)*N_5),1) +IF(MOD($F18-(QUOTIENT($F18,N_5)*N_5),1)=0,0,1) +IF(MOD($F18,N_5)=0,C_L6,0)) | O18: =INDEX(T_L1[],G18) -> Almond Butter, | P18: =INDEX(T_L2[],H18) -> Peanut Butter | Q18: =INDEX(T_L3[],I18) -> #VALUE! | R18: =INDEX(T_L4[],J18) -> #VALUE! | S18: =INDEX(T_L5[],K18) -> #VALUE! | T18: =INDEX(T_L6[],L18) -> #VALUE! | X18: 15 | Y18: =COUNTIF(HELP!$G$3:$G$502,X18) -> 0 | Z18: =COUNTIF(HELP!$H$3:$H$502,X18) -> 14 | AA18: =COUNTIF(HELP!$I$3:$I$502,X18) -> 0 | AB18: =COUNTIF(HELP!$J$3:$J$502,X18) -> 0 | AC18: =COUNTIF(HELP!$K$3:$K$502,X18) -> 0 | AD18: =COUNTIF(HELP!$L$3:$L$502,X18) -> 0
F19: 17 | G19: =IF(OR($F19>N,G$2>N_LISTS),"",QUOTIENT($F19-(QUOTIENT($F19,N)*N),N_1) +IF(MOD($F19-(QUOTIENT($F19,N)*N),N_1)=0,0,1) +IF(MOD($F19,N)=0,C_L1,0)) -> 2 | H19: =IF(OR($F19>N,H$2>N_LISTS),"",QUOTIENT($F19-(QUOTIENT($F19,N_1)*N_1),N_2) +IF(MOD($F19-(QUOTIENT($F19,N_1)*N_1),N_2)=0,0,1) +IF(MOD($F19,N_1)=0,C_L2,0)) -> 2 | I19: =IF(OR($F19>N,I$2>N_LISTS),"",QUOTIENT($F19-(QUOTIENT($F19,N_2)*N_2),N_3) +IF(MOD($F19-(QUOTIENT($F19,N_2)*N_2),N_3)=0,0,1) +IF(MOD($F19,N_2)=0,C_L3,0)) | J19: =IF(OR($F19>N,J$2>N_LISTS),"",QUOTIENT($F19-(QUOTIENT($F19,N_3)*N_3),N_4) +IF(MOD($F19-(QUOTIENT($F19,N_3)*N_3),N_4)=0,0,1) +IF(MOD($F19,N_3)=0,C_L4,0)) | K19: =IF(OR($F19>N,K$2>N_LISTS),"",QUOTIENT($F19-(QUOTIENT($F19,N_4)*N_4),N_5) +IF(MOD($F19-(QUOTIENT($F19,N_4)*N_4),N_5)=0,0,1) +IF(MOD($F19,N_4)=0,C_L5,0)) | L19: =IF(OR($F19>N,L$2>N_LISTS),"",QUOTIENT($F19-(QUOTIENT($F19,N_5)*N_5),1) +IF(MOD($F19-(QUOTIENT($F19,N_5)*N_5),1)=0,0,1) +IF(MOD($F19,N_5)=0,C_L6,0)) | O19: =INDEX(T_L1[],G19) -> Almond Butter, | P19: =INDEX(T_L2[],H19) -> Almond Butter | Q19: =INDEX(T_L3[],I19) -> #VALUE! | R19: =INDEX(T_L4[],J19) -> #VALUE! | S19: =INDEX(T_L5[],K19) -> #VALUE! | T19: =INDEX(T_L6[],L19) -> #VALUE! | X19: 16 | Y19: =COUNTIF(HELP!$G$3:$G$502,X19) -> 0 | Z19: =COUNTIF(HELP!$H$3:$H$502,X19) -> 0 | AA19: =COUNTIF(HELP!$I$3:$I$502,X19) -> 0 | AB19: =COUNTIF(HELP!$J$3:$J$502,X19) -> 0 | AC19: =COUNTIF(HELP!$K$3:$K$502,X19) -> 0 | AD19: =COUNTIF(HELP!$L$3:$L$502,X19) -> 0
F20: 18 | G20: =IF(OR($F20>N,G$2>N_LISTS),"",QUOTIENT($F20-(QUOTIENT($F20,N)*N),N_1) +IF(MOD($F20-(QUOTIENT($F20,N)*N),N_1)=0,0,1) +IF(MOD($F20,N)=0,C_L1,0)) -> 2 | H20: =IF(OR($F20>N,H$2>N_LISTS),"",QUOTIENT($F20-(QUOTIENT($F20,N_1)*N_1),N_2) +IF(MOD($F20-(QUOTIENT($F20,N_1)*N_1),N_2)=0,0,1) +IF(MOD($F20,N_1)=0,C_L2,0)) -> 3 | I20: =IF(OR($F20>N,I$2>N_LISTS),"",QUOTIENT($F20-(QUOTIENT($F20,N_2)*N_2),N_3) +IF(MOD($F20-(QUOTIENT($F20,N_2)*N_2),N_3)=0,0,1) +IF(MOD($F20,N_2)=0,C_L3,0)) | J20: =IF(OR($F20>N,J$2>N_LISTS),"",QUOTIENT($F20-(QUOTIENT($F20,N_3)*N_3),N_4) +IF(MOD($F20-(QUOTIENT($F20,N_3)*N_3),N_4)=0,0,1) +IF(MOD($F20,N_3)=0,C_L4,0)) | K20: =IF(OR($F20>N,K$2>N_LISTS),"",QUOTIENT($F20-(QUOTIENT($F20,N_4)*N_4),N_5) +IF(MOD($F20-(QUOTIENT($F20,N_4)*N_4),N_5)=0,0,1) +IF(MOD($F20,N_4)=0,C_L5,0)) | L20: =IF(OR($F20>N,L$2>N_LISTS),"",QUOTIENT($F20-(QUOTIENT($F20,N_5)*N_5),1) +IF(MOD($F20-(QUOTIENT($F20,N_5)*N_5),1)=0,0,1) +IF(MOD($F20,N_5)=0,C_L6,0)) | O20: =INDEX(T_L1[],G20) -> Almond Butter, | P20: =INDEX(T_L2[],H20) -> Cashew Butter | Q20: =INDEX(T_L3[],I20) -> #VALUE! | R20: =INDEX(T_L4[],J20) -> #VALUE! | S20: =INDEX(T_L5[],K20) -> #VALUE! | T20: =INDEX(T_L6[],L20) -> #VALUE! | X20: 17 | Y20: =COUNTIF(HELP!$G$3:$G$502,X20) -> 0 | Z20: =COUNTIF(HELP!$H$3:$H$502,X20) -> 0 | AA20: =COUNTIF(HELP!$I$3:$I$502,X20) -> 0 | AB20: =COUNTIF(HELP!$J$3:$J$502,X20) -> 0 | AC20: =COUNTIF(HELP!$K$3:$K$502,X20) -> 0 | AD20: =COUNTIF(HELP!$L$3:$L$502,X20) -> 0
F21: 19 | G21: =IF(OR($F21>N,G$2>N_LISTS),"",QUOTIENT($F21-(QUOTIENT($F21,N)*N),N_1) +IF(MOD($F21-(QUOTIENT($F21,N)*N),N_1)=0,0,1) +IF(MOD($F21,N)=0,C_L1,0)) -> 2 | H21: =IF(OR($F21>N,H$2>N_LISTS),"",QUOTIENT($F21-(QUOTIENT($F21,N_1)*N_1),N_2) +IF(MOD($F21-(QUOTIENT($F21,N_1)*N_1),N_2)=0,0,1) +IF(MOD($F21,N_1)=0,C_L2,0)) -> 4 | I21: =IF(OR($F21>N,I$2>N_LISTS),"",QUOTIENT($F21-(QUOTIENT($F21,N_2)*N_2),N_3) +IF(MOD($F21-(QUOTIENT($F21,N_2)*N_2),N_3)=0,0,1) +IF(MOD($F21,N_2)=0,C_L3,0)) | J21: =IF(OR($F21>N,J$2>N_LISTS),"",QUOTIENT($F21-(QUOTIENT($F21,N_3)*N_3),N_4) +IF(MOD($F21-(QUOTIENT($F21,N_3)*N_3),N_4)=0,0,1) +IF(MOD($F21,N_3)=0,C_L4,0)) | K21: =IF(OR($F21>N,K$2>N_LISTS),"",QUOTIENT($F21-(QUOTIENT($F21,N_4)*N_4),N_5) +IF(MOD($F21-(QUOTIENT($F21,N_4)*N_4),N_5)=0,0,1) +IF(MOD($F21,N_4)=0,C_L5,0)) | L21: =IF(OR($F21>N,L$2>N_LISTS),"",QUOTIENT($F21-(QUOTIENT($F21,N_5)*N_5),1) +IF(MOD($F21-(QUOTIENT($F21,N_5)*N_5),1)=0,0,1) +IF(MOD($F21,N_5)=0,C_L6,0)) | O21: =INDEX(T_L1[],G21) -> Almond Butter, | P21: =INDEX(T_L2[],H21) -> Chia Seeds | Q21: =INDEX(T_L3[],I21) -> #VALUE! | R21: =INDEX(T_L4[],J21) -> #VALUE! | S21: =INDEX(T_L5[],K21) -> #VALUE! | T21: =INDEX(T_L6[],L21) -> #VALUE! | X21: 18 | Y21: =COUNTIF(HELP!$G$3:$G$502,X21) -> 0 | Z21: =COUNTIF(HELP!$H$3:$H$502,X21) -> 0 | AA21: =COUNTIF(HELP!$I$3:$I$502,X21) -> 0 | AB21: =COUNTIF(HELP!$J$3:$J$502,X21) -> 0 | AC21: =COUNTIF(HELP!$K$3:$K$502,X21) -> 0 | AD21: =COUNTIF(HELP!$L$3:$L$502,X21) -> 0
F22: 20 | G22: =IF(OR($F22>N,G$2>N_LISTS),"",QUOTIENT($F22-(QUOTIENT($F22,N)*N),N_1) +IF(MOD($F22-(QUOTIENT($F22,N)*N),N_1)=0,0,1) +IF(MOD($F22,N)=0,C_L1,0)) -> 2 | H22: =IF(OR($F22>N,H$2>N_LISTS),"",QUOTIENT($F22-(QUOTIENT($F22,N_1)*N_1),N_2) +IF(MOD($F22-(QUOTIENT($F22,N_1)*N_1),N_2)=0,0,1) +IF(MOD($F22,N_1)=0,C_L2,0)) -> 5 | I22: =IF(OR($F22>N,I$2>N_LISTS),"",QUOTIENT($F22-(QUOTIENT($F22,N_2)*N_2),N_3) +IF(MOD($F22-(QUOTIENT($F22,N_2)*N_2),N_3)=0,0,1) +IF(MOD($F22,N_2)=0,C_L3,0)) | J22: =IF(OR($F22>N,J$2>N_LISTS),"",QUOTIENT($F22-(QUOTIENT($F22,N_3)*N_3),N_4) +IF(MOD($F22-(QUOTIENT($F22,N_3)*N_3),N_4)=0,0,1) +IF(MOD($F22,N_3)=0,C_L4,0)) | K22: =IF(OR($F22>N,K$2>N_LISTS),"",QUOTIENT($F22-(QUOTIENT($F22,N_4)*N_4),N_5) +IF(MOD($F22-(QUOTIENT($F22,N_4)*N_4),N_5)=0,0,1) +IF(MOD($F22,N_4)=0,C_L5,0)) | L22: =IF(OR($F22>N,L$2>N_LISTS),"",QUOTIENT($F22-(QUOTIENT($F22,N_5)*N_5),1) +IF(MOD($F22-(QUOTIENT($F22,N_5)*N_5),1)=0,0,1) +IF(MOD($F22,N_5)=0,C_L6,0)) | O22: =INDEX(T_L1[],G22) -> Almond Butter, | P22: =INDEX(T_L2[],H22) -> Flax Seeds | Q22: =INDEX(T_L3[],I22) -> #VALUE! | R22: =INDEX(T_L4[],J22) -> #VALUE! | S22: =INDEX(T_L5[],K22) -> #VALUE! | T22: =INDEX(T_L6[],L22) -> #VALUE! | X22: 19 | Y22: =COUNTIF(HELP!$G$3:$G$502,X22) -> 0 | Z22: =COUNTIF(HELP!$H$3:$H$502,X22) -> 0 | AA22: =COUNTIF(HELP!$I$3:$I$502,X22) -> 0 | AB22: =COUNTIF(HELP!$J$3:$J$502,X22) -> 0 | AC22: =COUNTIF(HELP!$K$3:$K$502,X22) -> 0 | AD22: =COUNTIF(HELP!$L$3:$L$502,X22) -> 0
F23: 21 | G23: =IF(OR($F23>N,G$2>N_LISTS),"",QUOTIENT($F23-(QUOTIENT($F23,N)*N),N_1) +IF(MOD($F23-(QUOTIENT($F23,N)*N),N_1)=0,0,1) +IF(MOD($F23,N)=0,C_L1,0)) -> 2 | H23: =IF(OR($F23>N,H$2>N_LISTS),"",QUOTIENT($F23-(QUOTIENT($F23,N_1)*N_1),N_2) +IF(MOD($F23-(QUOTIENT($F23,N_1)*N_1),N_2)=0,0,1) +IF(MOD($F23,N_1)=0,C_L2,0)) -> 6 | I23: =IF(OR($F23>N,I$2>N_LISTS),"",QUOTIENT($F23-(QUOTIENT($F23,N_2)*N_2),N_3) +IF(MOD($F23-(QUOTIENT($F23,N_2)*N_2),N_3)=0,0,1) +IF(MOD($F23,N_2)=0,C_L3,0)) | J23: =IF(OR($F23>N,J$2>N_LISTS),"",QUOTIENT($F23-(QUOTIENT($F23,N_3)*N_3),N_4) +IF(MOD($F23-(QUOTIENT($F23,N_3)*N_3),N_4)=0,0,1) +IF(MOD($F23,N_3)=0,C_L4,0)) | K23: =IF(OR($F23>N,K$2>N_LISTS),"",QUOTIENT($F23-(QUOTIENT($F23,N_4)*N_4),N_5) +IF(MOD($F23-(QUOTIENT($F23,N_4)*N_4),N_5)=0,0,1) +IF(MOD($F23,N_4)=0,C_L5,0)) | L23: =IF(OR($F23>N,L$2>N_LISTS),"",QUOTIENT($F23-(QUOTIENT($F23,N_5)*N_5),1) +IF(MOD($F23-(QUOTIENT($F23,N_5)*N_5),1)=0,0,1) +IF(MOD($F23,N_5)=0,C_L6,0)) | O23: =INDEX(T_L1[],G23) -> Almond Butter, | P23: =INDEX(T_L2[],H23) -> Hemp Seeds | Q23: =INDEX(T_L3[],I23) -> #VALUE! | R23: =INDEX(T_L4[],J23) -> #VALUE! | S23: =INDEX(T_L5[],K23) -> #VALUE! | T23: =INDEX(T_L6[],L23) -> #VALUE! | X23: 20 | Y23: =COUNTIF(HELP!$G$3:$G$502,X23) -> 0 | Z23: =COUNTIF(HELP!$H$3:$H$502,X23) -> 0 | AA23: =COUNTIF(HELP!$I$3:$I$502,X23) -> 0 | AB23: =COUNTIF(HELP!$J$3:$J$502,X23) -> 0 | AC23: =COUNTIF(HELP!$K$3:$K$502,X23) -> 0 | AD23: =COUNTIF(HELP!$L$3:$L$502,X23) -> 0
... F28: 26 | G28: =IF(OR($F28>N,G$2>N_LISTS),"",QUOTIENT($F28-(QUOTIENT($F28,N)*N),N_1) +IF(MOD($F28-(QUOTIENT($F28,N)*N),N_1)=0,0,1) +IF(MOD($F28,N)=0,C_L1,0)) -> 2 | H28: =IF(OR($F28>N,H$2>N_LISTS),"",QUOTIENT($F28-(QUOTIENT($F28,N_1)*N_1),N_2) +IF(MOD($F28-(QUOTIENT($F28,N_1)*N_1),N_2)=0,0,1) +IF(MOD($F28,N_1)=0,C_L2,0)) -> 11 | I28: =IF(OR($F28>N,I$2>N_LISTS),"",QUOTIENT($F28-(QUOTIENT($F28,N_2)*N_2),N_3) +IF(MOD($F28-(QUOTIENT($F28,N_2)*N_2),N_3)=0,0,1) +IF(MOD($F28,N_2)=0,C_L3,0)) | J28: =IF(OR($F28>N,J$2>N_LISTS),"",QUOTIENT($F28-(QUOTIENT($F28,N_3)*N_3),N_4) +IF(MOD($F28-(QUOTIENT($F28,N_3)*N_3),N_4)=0,0,1) +IF(MOD($F28,N_3)=0,C_L4,0)) | K28: =IF(OR($F28>N,K$2>N_LISTS),"",QUOTIENT($F28-(QUOTIENT($F28,N_4)*N_4),N_5) +IF(MOD($F28-(QUOTIENT($F28,N_4)*N_4),N_5)=0,0,1) +IF(MOD($F28,N_4)=0,C_L5,0)) | L28: =IF(OR($F28>N,L$2>N_LISTS),"",QUOTIENT($F28-(QUOTIENT($F28,N_5)*N_5),1) +IF(MOD($F28-(QUOTIENT($F28,N_5)*N_5),1)=0,0,1) +IF(MOD($F28,N_5)=0,C_L6,0)) | O28: =INDEX(T_L1[],G28) -> Almond Butter, | P28: =INDEX(T_L2[],H28) -> Pecans | Q28: =INDEX(T_L3[],I28) -> #VALUE! | R28: =INDEX(T_L4[],J28) -> #VALUE! | S28: =INDEX(T_L5[],K28) -> #VALUE! | T28: =INDEX(T_L6[],L28) -> #VALUE! | X28: 25 | Y28: =COUNTIF(HELP!$G$3:$G$502,X28) -> 0 | Z28: =COUNTIF(HELP!$H$3:$H$502,X28) -> 0 | AA28: =COUNTIF(HELP!$I$3:$I$502,X28) -> 0 | AB28: =COUNTIF(HELP!$J$3:$J$502,X28) -> 0 | AC28: =COUNTIF(HELP!$K$3:$K$502,X28) -> 0 | AD28: =COUNTIF(HELP!$L$3:$L$502,X28) -> 0
F29: 27 | G29: =IF(OR($F29>N,G$2>N_LISTS),"",QUOTIENT($F29-(QUOTIENT($F29,N)*N),N_1) +IF(MOD($F29-(QUOTIENT($F29,N)*N),N_1)=0,0,1) +IF(MOD($F29,N)=0,C_L1,0)) -> 2 | H29: =IF(OR($F29>N,H$2>N_LISTS),"",QUOTIENT($F29-(QUOTIENT($F29,N_1)*N_1),N_2) +IF(MOD($F29-(QUOTIENT($F29,N_1)*N_1),N_2)=0,0,1) +IF(MOD($F29,N_1)=0,C_L2,0)) -> 12 | I29: =IF(OR($F29>N,I$2>N_LISTS),"",QUOTIENT($F29-(QUOTIENT($F29,N_2)*N_2),N_3) +IF(MOD($F29-(QUOTIENT($F29,N_2)*N_2),N_3)=0,0,1) +IF(MOD($F29,N_2)=0,C_L3,0)) | J29: =IF(OR($F29>N,J$2>N_LISTS),"",QUOTIENT($F29-(QUOTIENT($F29,N_3)*N_3),N_4) +IF(MOD($F29-(QUOTIENT($F29,N_3)*N_3),N_4)=0,0,1) +IF(MOD($F29,N_3)=0,C_L4,0)) | K29: =IF(OR($F29>N,K$2>N_LISTS),"",QUOTIENT($F29-(QUOTIENT($F29,N_4)*N_4),N_5) +IF(MOD($F29-(QUOTIENT($F29,N_4)*N_4),N_5)=0,0,1) +IF(MOD($F29,N_4)=0,C_L5,0)) | L29: =IF(OR($F29>N,L$2>N_LISTS),"",QUOTIENT($F29-(QUOTIENT($F29,N_5)*N_5),1) +IF(MOD($F29-(QUOTIENT($F29,N_5)*N_5),1)=0,0,1) +IF(MOD($F29,N_5)=0,C_L6,0)) | O29: =INDEX(T_L1[],G29) -> Almond Butter, | P29: =INDEX(T_L2[],H29) -> Macadamia Nuts | Q29: =INDEX(T_L3[],I29) -> #VALUE! | R29: =INDEX(T_L4[],J29) -> #VALUE! | S29: =INDEX(T_L5[],K29) -> #VALUE! | T29: =INDEX(T_L6[],L29) -> #VALUE!
F30: 28 | G30: =IF(OR($F30>N,G$2>N_LISTS),"",QUOTIENT($F30-(QUOTIENT($F30,N)*N),N_1) +IF(MOD($F30-(QUOTIENT($F30,N)*N),N_1)=0,0,1) +IF(MOD($F30,N)=0,C_L1,0)) -> 2 | H30: =IF(OR($F30>N,H$2>N_LISTS),"",QUOTIENT($F30-(QUOTIENT($F30,N_1)*N_1),N_2) +IF(MOD($F30-(QUOTIENT($F30,N_1)*N_1),N_2)=0,0,1) +IF(MOD($F30,N_1)=0,C_L2,0)) -> 13 | I30: =IF(OR($F30>N,I$2>N_LISTS),"",QUOTIENT($F30-(QUOTIENT($F30,N_2)*N_2),N_3) +IF(MOD($F30-(QUOTIENT($F30,N_2)*N_2),N_3)=0,0,1) +IF(MOD($F30,N_2)=0,C_L3,0)) | J30: =IF(OR($F30>N,J$2>N_LISTS),"",QUOTIENT($F30-(QUOTIENT($F30,N_3)*N_3),N_4) +IF(MOD($F30-(QUOTIENT($F30,N_3)*N_3),N_4)=0,0,1) +IF(MOD($F30,N_3)=0,C_L4,0)) | K30: =IF(OR($F30>N,K$2>N_LISTS),"",QUOTIENT($F30-(QUOTIENT($F30,N_4)*N_4),N_5) +IF(MOD($F30-(QUOTIENT($F30,N_4)*N_4),N_5)=0,0,1) +IF(MOD($F30,N_4)=0,C_L5,0)) | L30: =IF(OR($F30>N,L$2>N_LISTS),"",QUOTIENT($F30-(QUOTIENT($F30,N_5)*N_5),1) +IF(MOD($F30-(QUOTIENT($F30,N_5)*N_5),1)=0,0,1) +IF(MOD($F30,N_5)=0,C_L6,0)) | O30: =INDEX(T_L1[],G30) -> Almond Butter, | P30: =INDEX(T_L2[],H30) -> Tahini | Q30: =INDEX(T_L3[],I30) -> #VALUE! | R30: =INDEX(T_L4[],J30) -> #VALUE! | S30: =INDEX(T_L5[],K30) -> #VALUE! | T30: =INDEX(T_L6[],L30) -> #VALUE!
